Workbook
Name participantes: Participantes!$A$2:$C$91

Sheet Bases
B1: Torneo entre amigos
B2: Participación en el torneo basado en las quinielas tradicionales
A3: Torneos: | B3: Todos los partidos de la Eurocopa 2016 (hasta la final)
A4: Bases: | B4: Esta competencia toma como base las quinielas tracionales. Consiste en lo siguiente: 1.- El participante debe pronosticar por cada partido el resultado que tendrá, indicando los goles anotados por los equipos. 2.- El torneo se dividirá en 4 semanas. Sem 1 - 10 al 16 de junio. (18 partidos) Sem 2 - 17 al 24 de junio. (18 partidos) Sem 3 - 25 al 27 de junio. (8 partidos) Sem 4 - 30 de junio al 10 de julio. (7 partidos) 3.- Por cada semana se jugarán tres puntos adicionales por lo que serán un total de 12 puntos, apoyando con esto a generar desempates. 4.- Existe un solo ganador de la bolsa y este será el participante con mayor número de puntos obtenidos durante el torneo. En caso de empates la bolsa se dividirá en partes iguales entre el número de participates que se encuentren en esta situación.
A5: Puntos: | B5: La obtención de los puntos es de la siguiente forma: 1.- Se obtendrá un punto por pronosticar correctamente al ganador o empate por cualquier resultado que se presente. Ejemplo: España 2 - 1 Francia. En caso de ganar España por este u otro resultado se genera el punto. 2.- Se obtiene un segundo punto por cada partido, cuando se pronostique correctamente el resultado del mismo, es decir, siguiendo con el ejemplo anterior, en caso de la victoria española por 2 a 1 se generará el punto. 3.- El participante pronosticará la cantidad de goles que se anotarán por cada semana, de forma independiente a los indicados en los resultados pronosticados de los partidos. Si la cuota efectivamente se cumple el participaten genera 3 puntos por cada semana que acierte.
A6: Ganador: | B6: Un único ganador, el participante con mayor número de puntos generados se convierte en campeón de la Eurocopa 2016 y se lleva la bolsa acumulada. En caso de existir dos o más participantes ganadores se dividirá la bolsa en proporciones iguales entre ellos.
A7: Costo: | B7: 200
A8: Bolsa: | B8: =COUNT(Participantes!$A$2:$A$91) * B7 -> 1200
A9: ¿Participas? | B9: Si. Ve a la pestaña de "Participantes" y registra tus datos y tu id en la lista.
A10: Cierre de incripción: | B10: Jueve 9 de junio a las 7pm.

Sheet Participantes
A1: id | B1: Nombre | C1: Lugar | D1: Pagado
A2: 1 | B2: Carlos Ruíz | C2: Ver. | D2: No | E2: 0
A3: 2 | B3: Javier Ruíz | C3: Ver. | D3: No | E3: 0
A4: 3 | B4: Jair Salomón | C4: Tamp. | D4: No | E4: 0
A5: 4 | B5: Kevin Salomón | C5: Ags. | D5: No | E5: 0
A6: 5 | B6: Roberto Ruíz | C6: Yuc. | D6: No | E6: 0
A7: 6 | B7: Francisco | C7: Tamp. | D7: No | E7: 0
E8: =SUM(E2:E7) -> 0

Sheet Tabla general
B1: Tabla General
A3: id | B3: Participante | C3: Pronostico de resultado. | E3: Lugar | K3: Puntos
A4: 5 | B4: =VLOOKUP($A4,[0]!participantes,2) -> Roberto Ruíz | C4: =SUM('Jornada 1 - Partidos'!S18, 'Jornada 2 - Partidos'!S18, 'Jornada 3 - Partidos'!S18,'Octavos - Partidos'!S14,'Finales - Partidos'!S13) -> 36 | E4: 1 | K4: Partido | L4: 1
A5: 4 | B5: =VLOOKUP($A5,[0]!participantes,2) -> Kevin Salomón | C5: =SUM('Jornada 1 - Partidos'!P18, 'Jornada 2 - Partidos'!P18, 'Jornada 3 - Partidos'!P18,'Octavos - Partidos'!P14,'Finales - Partidos'!P13) -> 35 | E5: 2 | K5: Resultado | L5: 1
A6: 1 | B6: =VLOOKUP($A6,[0]!participantes,2) -> Carlos Ruíz | C6: =SUM('Jornada 1 - Partidos'!G$18, 'Jornada 2 - Partidos'!G$18, 'Jornada 3 - Partidos'!G$18,'Octavos - Partidos'!G14,'Finales - Partidos'!G13) -> 33 | E6: 3 | K6: Goles | L6: 3
A7: 2 | B7: =VLOOKUP($A7,[0]!participantes,2) -> Javier Ruíz | C7: =SUM('Jornada 1 - Partidos'!J18, 'Jornada 2 - Partidos'!J18, 'Jornada 3 - Partidos'!J18,'Octavos - Partidos'!J14,'Finales - Partidos'!J13) -> 31 | E7: 4
A8: 3 | B8: =VLOOKUP($A8,[0]!participantes,2) -> Jair Salomón | C8: =SUM('Jornada 1 - Partidos'!M18, 'Jornada 2 - Partidos'!M18, 'Jornada 3 - Partidos'!M18,'Octavos - Partidos'!M14,'Finales - Partidos'!M13) -> 29 | E8: 5

Sheet Jornada 1 - Partidos
A1: Partidos del 10 al 14 de junio
B2: ids | E2: 1 | H2: 2 | K2: 3 | N2: 4 | Q2: 5
B3: Participantes | C3: Goles oficiales | E3: =VLOOKUP(E$2,[0]!participantes,2) -> Carlos Ruíz | G3: Puntos | H3: =VLOOKUP(H$2,[0]!participantes,2) -> Javier Ruíz | J3: Puntos | K3: =VLOOKUP(K$2,[0]!participantes,2) -> Jair Salomón | M3: Puntos | N3: =VLOOKUP(N$2,[0]!participantes,2) -> Kevin Salomón | P3: Puntos | Q3: =VLOOKUP(Q$2,[0]!participantes,2) -> Roberto Ruíz | S3: Puntos
B4: Goles de la semana | C4: =SUM(C6:D17) -> 22 | E4: =SUM(E6:F17) -> 26 | G4: =IF(E4=$C$4,'Tabla general'!$L$6,0) -> 0 | H4: =SUM(H6:I17) -> 24 | J4: =IF(H4=$C$4,'Tabla general'!$L$6,0) -> 0 | K4: =SUM(K6:L17) -> 31 | M4: =IF(K4=$C$4,'Tabla general'!$L$6,0) -> 0 | N4: =SUM(N6:O17) -> 31 | P4: =IF(N4=$C$4,'Tabla general'!$L$6,0) -> 0 | Q4: =SUM(Q6:R17) -> 27 | S4: =IF(Q4=$C$4,'Tabla general'!$L$6,0) -> 0
A5: Partidos | C5: Marcadores oficiales | E5: Predicción | G5: Puntos | H5: Predicción | J5: Puntos | K5: Predicción | M5: Puntos | N5: Predicción | P5: Puntos | Q5: Predicción | S5: Puntos
A6: Francia | B6: Rumania | C6: 2 | D6: 1 | E6: 2 | F6: 0 | G6: =IF(AND($C6="",$D6=""),0,IF(AND($C6>$D6,E6>F6),'Tabla general'!$L$4,IF(AND($D6>$C6,F6>E6),'Tabla general'!$L$4,IF(AND($C6=$D6,E6=F6),'Tabla general'!$L$4,0))) + IF(AND($C6=E6,$D6=F6),'Tabla general'!$L$5,0)) -> 1 | H6: 2 | I6: 0 | J6: =IF(AND($C6="",$D6=""),0,IF(AND($C6>$D6,H6>I6),'Tabla general'!$L$4,IF(AND($D6>$C6,I6>H6),'Tabla general'!$L$4,IF(AND($C6=$D6,H6=I6),'Tabla general'!$L$4,0))) + IF(AND($C6=H6,$D6=I6),'Tabla general'!$L$5,0)) -> 1 | K6: 3 | L6: 0 | M6: =IF(AND($C6="",$D6=""),0,IF(AND($C6>$D6,K6>L6),'Tabla general'!$L$4,IF(AND($D6>$C6,L6>K6),'Tabla general'!$L$4,IF(AND($C6=$D6,K6=L6),'Tabla general'!$L$4,0))) + IF(AND($C6=K6,$D6=L6),'Tabla general'!$L$5,0)) -> 1 | N6: 2 | O6: 0 | P6: =IF(AND($C6="",$D6=""),0,IF(AND($C6>$D6,N6>O6),'Tabla general'!$L$4,IF(AND($D6>$C6,O6>N6),'Tabla general'!$L$4,IF(AND($C6=$D6,N6=O6),'Tabla general'!$L$4,0))) + IF(AND($C6=N6,$D6=O6),'Tabla general'!$L$5,0)) -> 1 | Q6: 2 | R6: 0 | S6: =IF(AND($C6="",$D6=""),0,IF(AND($C6>$D6,Q6>R6),'Tabla general'!$L$4,IF(AND($D6>$C6,R6>Q6),'Tabla general'!$L$4,IF(AND($C6=$D6,Q6=R6),'Tabla general'!$L$4,0))) + IF(AND($C6=Q6,$D6=R6),'Tabla general'!$L$5,0)) -> 1
A7: Albania | B7: Suiza | C7: 0 | D7: 1 | E7: 0 | F7: 1 | G7: =IF(AND($C7="",$D7=""),0,IF(AND($C7>$D7,E7>F7),'Tabla general'!$L$4,IF(AND($D7>$C7,F7>E7),'Tabla general'!$L$4,IF(AND($C7=$D7,E7=F7),'Tabla general'!$L$4,0))) + IF(AND($C7=E7,$D7=F7),'Tabla general'!$L$5,0)) -> 2 | H7: 0 | I7: 1 | J7: =IF(AND($C7="",$D7=""),0,IF(AND($C7>$D7,H7>I7),'Tabla general'!$L$4,IF(AND($D7>$C7,I7>H7),'Tabla general'!$L$4,IF(AND($C7=$D7,H7=I7),'Tabla general'!$L$4,0))) + IF(AND($C7=H7,$D7=I7),'Tabla general'!$L$5,0)) -> 2 | K7: 1 | L7: 2 | M7: =IF(AND($C7="",$D7=""),0,IF(AND($C7>$D7,K7>L7),'Tabla general'!$L$4,IF(AND($D7>$C7,L7>K7),'Tabla general'!$L$4,IF(AND($C7=$D7,K7=L7),'Tabla general'!$L$4,0))) + IF(AND($C7=K7,$D7=L7),'Tabla general'!$L$5,0)) -> 1 | N7: 0 | O7: 1 | P7: =IF(AND($C7="",$D7=""),0,IF(AND($C7>$D7,N7>O7),'Tabla general'!$L$4,IF(AND($D7>$C7,O7>N7),'Tabla general'!$L$4,IF(AND($C7=$D7,N7=O7),'Tabla general'!$L$4,0))) + IF(AND($C7=N7,$D7=O7),'Tabla general'!$L$5,0)) -> 2 | Q7: 0 | R7: 2 | S7: =IF(AND($C7="",$D7=""),0,IF(AND($C7>$D7,Q7>R7),'Tabla general'!$L$4,IF(AND($D7>$C7,R7>Q7),'Tabla general'!$L$4,IF(AND($C7=$D7,Q7=R7),'Tabla general'!$L$4,0))) + IF(AND($C7=Q7,$D7=R7),'Tabla general'!$L$5,0)) -> 1
A8: Gales | B8: Eslovaquia | C8: 2 | D8: 1 | E8: 2 | F8: 1 | G8: =IF(AND($C8="",$D8=""),0,IF(AND($C8>$D8,E8>F8),'Tabla general'!$L$4,IF(AND($D8>$C8,F8>E8),'Tabla general'!$L$4,IF(AND($C8=$D8,E8=F8),'Tabla general'!$L$4,0))) + IF(AND($C8=E8,$D8=F8),'Tabla general'!$L$5,0)) -> 2 | H8: 1 | I8: 0 | J8: =IF(AND($C8="",$D8=""),0,IF(AND($C8>$D8,H8>I8),'Tabla general'!$L$4,IF(AND($D8>$C8,I8>H8),'Tabla general'!$L$4,IF(AND($C8=$D8,H8=I8),'Tabla general'!$L$4,0))) + IF(AND($C8=H8,$D8=I8),'Tabla general'!$L$5,0)) -> 1 | K8: 2 | L8: 0 | M8: =IF(AND($C8="",$D8=""),0,IF(AND($C8>$D8,K8>L8),'Tabla general'!$L$4,IF(AND($D8>$C8,L8>K8),'Tabla general'!$L$4,IF(AND($C8=$D8,K8=L8),'Tabla general'!$L$4,0))) + IF(AND($C8=K8,$D8=L8),'Tabla general'!$L$5,0)) -> 1 | N8: 1 | O8: 3 | P8: =IF(AND($C8="",$D8=""),0,IF(AND($C8>$D8,N8>O8),'Tabla general'!$L$4,IF(AND($D8>$C8,O8>N8),'Tabla general'!$L$4,IF(AND($C8=$D8,N8=O8),'Tabla general'!$L$4,0))) + IF(AND($C8=N8,$D8=O8),'Tabla general'!$L$5,0)) -> 0 | Q8: 1 | R8: 0 | S8: =IF(AND($C8="",$D8=""),0,IF(AND($C8>$D8,Q8>R8),'Tabla general'!$L$4,IF(AND($D8>$C8,R8>Q8),'Tabla general'!$L$4,IF(AND($C8=$D8,Q8=R8),'Tabla general'!$L$4,0))) + IF(AND($C8=Q8,$D8=R8),'Tabla general'!$L$5,0)) -> 1
A9: Inglaterra | B9: Rusia | C9: 1 | D9: 1 | E9: 1 | F9: 1 | G9: =IF(AND($C9="",$D9=""),0,IF(AND($C9>$D9,E9>F9),'Tabla general'!$L$4,IF(AND($D9>$C9,F9>E9),'Tabla general'!$L$4,IF(AND($C9=$D9,E9=F9),'Tabla general'!$L$4,0))) + IF(AND($C9=E9,$D9=F9),'Tabla general'!$L$5,0)) -> 2 | H9: 2 | I9: 2 | J9: =IF(AND($C9="",$D9=""),0,IF(AND($C9>$D9,H9>I9),'Tabla general'!$L$4,IF(AND($D9>$C9,I9>H9),'Tabla general'!$L$4,IF(AND($C9=$D9,H9=I9),'Tabla general'!$L$4,0))) + IF(AND($C9=H9,$D9=I9),'Tabla general'!$L$5,0)) -> 1 | K9: 2 | L9: 0 | M9: =IF(AND($C9="",$D9=""),0,IF(AND($C9>$D9,K9>L9),'Tabla general'!$L$4,IF(AND($D9>$C9,L9>K9),'Tabla general'!$L$4,IF(AND($C9=$D9,K9=L9),'Tabla general'!$L$4,0))) + IF(AND($C9=K9,$D9=L9),'Tabla general'!$L$5,0)) -> 0 | N9: 2 | O9: 1 | P9: =IF(AND($C9="",$D9=""),0,IF(AND($C9>$D9,N9>O9),'Tabla general'!$L$4,IF(AND($D9>$C9,O9>N9),'Tabla general'!$L$4,IF(AND($C9=$D9,N9=O9),'Tabla general'!$L$4,0))) + IF(AND($C9=N9,$D9=O9),'Tabla general'!$L$5,0)) -> 0 | Q9: 2 | R9: 1 | S9: =IF(AND($C9="",$D9=""),0,IF(AND($C9>$D9,Q9>R9),'Tabla general'!$L$4,IF(AND($D9>$C9,R9>Q9),'Tabla general'!$L$4,IF(AND($C9=$D9,Q9=R9),'Tabla general'!$L$4,0))) + IF(AND($C9=Q9,$D9=R9),'Tabla general'!$L$5,0)) -> 0
A10: Turquia | B10: Croacia | C10: 0 | D10: 1 | E10: 1 | F10: 2 | G10: =IF(AND($C10="",$D10=""),0,IF(AND($C10>$D10,E10>F10),'Tabla general'!$L$4,IF(AND($D10>$C10,F10>E10),'Tabla general'!$L$4,IF(AND($C10=$D10,E10=F10),'Tabla general'!$L$4,0))) + IF(AND($C10=E10,$D10=F10),'Tabla general'!$L$5,0)) -> 1 | H10: 1 | I10: 2 | J10: =IF(AND($C10="",$D10=""),0,IF(AND($C10>$D10,H10>I10),'Tabla general'!$L$4,IF(AND($D10>$C10,I10>H10),'Tabla general'!$L$4,IF(AND($C10=$D10,H10=I10),'Tabla general'!$L$4,0))) + IF(AND($C10=H10,$D10=I10),'Tabla general'!$L$5,0)) -> 1 | K10: 2 | L10: 1 | M10: =IF(AND($C10="",$D10=""),0,IF(AND($C10>$D10,K10>L10),'Tabla general'!$L$4,IF(AND($D10>$C10,L10>K10),'Tabla general'!$L$4,IF(AND($C10=$D10,K10=L10),'Tabla general'!$L$4,0))) + IF(AND($C10=K10,$D10=L10),'Tabla general'!$L$5,0)) -> 0 | N10: 2 | O10: 2 | P10: =IF(AND($C10="",$D10=""),0,IF(AND($C10>$D10,N10>O10),'Tabla general'!$L$4,IF(AND($D10>$C10,O10>N10),'Tabla general'!$L$4,IF(AND($C10=$D10,N10=O10),'Tabla general'!$L$4,0))) + IF(AND($C10=N10,$D10=O10),'Tabla general'!$L$5,0)) -> 0 | Q10: 1 | R10: 2 | S10: =IF(AND($C10="",$D10=""),0,IF(AND($C10>$D10,Q10>R10),'Tabla general'!$L$4,IF(AND($D10>$C10,R10>Q10),'Tabla general'!$L$4,IF(AND($C10=$D10,Q10=R10),'Tabla general'!$L$4,0))) + IF(AND($C10=Q10,$D10=R10),'Tabla general'!$L$5,0)) -> 1
A11: Polonia | B11: Irlanda del norte | C11: 1 | D11: 0 | E11: 3 | F11: 1 | G11: =IF(AND($C11="",$D11=""),0,IF(AND($C11>$D11,E11>F11),'Tabla general'!$L$4,IF(AND($D11>$C11,F11>E11),'Tabla general'!$L$4,IF(AND($C11=$D11,E11=F11),'Tabla general'!$L$4,0))) + IF(AND($C11=E11,$D11=F11),'Tabla general'!$L$5,0)) -> 1 | H11: 0 | I11: 0 | J11: =IF(AND($C11="",$D11=""),0,IF(AND($C11>$D11,H11>I11),'Tabla general'!$L$4,IF(AND($D11>$C11,I11>H11),'Tabla general'!$L$4,IF(AND($C11=$D11,H11=I11),'Tabla general'!$L$4,0))) + IF(AND($C11=H11,$D11=I11),'Tabla general'!$L$5,0)) -> 0 | K11: 1 | L11: 1 | M11: =IF(AND($C11="",$D11=""),0,IF(AND($C11>$D11,K11>L11),'Tabla general'!$L$4,IF(AND($D11>$C11,L11>K11),'Tabla general'!$L$4,IF(AND($C11=$D11,K11=L11),'Tabla general'!$L$4,0))) + IF(AND($C11=K11,$D11=L11),'Tabla general'!$L$5,0)) -> 0 | N11: 0 | O11: 0 | P11: =IF(AND($C11="",$D11=""),0,IF(AND($C11>$D11,N11>O11),'Tabla general'!$L$4,IF(AND($D11>$C11,O11>N11),'Tabla general'!$L$4,IF(AND($C11=$D11,N11=O11),'Tabla general'!$L$4,0))) + IF(AND($C11=N11,$D11=O11),'Tabla general'!$L$5,0)) -> 0 | Q11: 1 | R11: 1 | S11: =IF(AND($C11="",$D11=""),0,IF(AND($C11>$D11,Q11>R11),'Tabla general'!$L$4,IF(AND($D11>$C11,R11>Q11),'Tabla general'!$L$4,IF(AND($C11=$D11,Q11=R11),'Tabla general'!$L$4,0))) + IF(AND($C11=Q11,$D11=R11),'Tabla general'!$L$5,0)) -> 0
A12: Alemania | B12: Ucrania | C12: 2 | D12: 0 | E12: 3 | F12: 0 | G12: =IF(AND($C12="",$D12=""),0,IF(AND($C12>$D12,E12>F12),'Tabla general'!$L$4,IF(AND($D12>$C12,F12>E12),'Tabla general'!$L$4,IF(AND($C12=$D12,E12=F12),'Tabla general'!$L$4,0))) + IF(AND($C12=E12,$D12=F12),'Tabla general'!$L$5,0)) -> 1 | H12: 3 | I12: 0 | J12: =IF(AND($C12="",$D12=""),0,IF(AND($C12>$D12,H12>I12),'Tabla general'!$L$4,IF(AND($D12>$C12,I12>H12),'Tabla general'!$L$4,IF(AND($C12=$D12,H12=I12),'Tabla general'!$L$4,0))) + IF(AND($C12=H12,$D12=I12),'Tabla general'!$L$5,0)) -> 1 | K12: 3 | L12: 0 | M12: =IF(AND($C12="",$D12=""),0,IF(AND($C12>$D12,K12>L12),'Tabla general'!$L$4,IF(AND($D12>$C12,L12>K12),'Tabla general'!$L$4,IF(AND($C12=$D12,K12=L12),'Tabla general'!$L$4,0))) + IF(AND($C12=K12,$D12=L12),'Tabla general'!$L$5,0)) -> 1 | N12: 3 | O12: 2 | P12: =IF(AND($C12="",$D12=""),0,IF(AND($C12>$D12,N12>O12),'Tabla general'!$L$4,IF(AND($D12>$C12,O12>N12),'Tabla general'!$L$4,IF(AND($C12=$D12,N12=O12),'Tabla general'!$L$4,0))) + IF(AND($C12=N12,$D12=O12),'Tabla general'!$L$5,0)) -> 1 | Q12: 2 | R12: 0 | S12: =IF(AND($C12="",$D12=""),0,IF(AND($C12>$D12,Q12>R12),'Tabla general'!$L$4,IF(AND($D12>$C12,R12>Q12),'Tabla general'!$L$4,IF(AND($C12=$D12,Q12=R12),'Tabla general'!$L$4,0))) + IF(AND($C12=Q12,$D12=R12),'Tabla general'!$L$5,0)) -> 2
A13: España | B13: Republica Checa | C13: 1 | D13: 0 | E13: 2 | F13: 1 | G13: =IF(AND($C13="",$D13=""),0,IF(AND($C13>$D13,E13>F13),'Tabla general'!$L$4,IF(AND($D13>$C13,F13>E13),'Tabla general'!$L$4,IF(AND($C13=$D13,E13=F13),'Tabla general'!$L$4,0))) + IF(AND($C13=E13,$D13=F13),'Tabla general'!$L$5,0)) -> 1 | H13: 2 | I13: 0 | J13: =IF(AND($C13="",$D13=""),0,IF(AND($C13>$D13,H13>I13),'Tabla general'!$L$4,IF(AND($D13>$C13,I13>H13),'Tabla general'!$L$4,IF(AND($C13=$D13,H13=I13),'Tabla general'!$L$4,0))) + IF(AND($C13=H13,$D13=I13),'Tabla general'!$L$5,0)) -> 1 | K13: 3 | L13: 1 | M13: =IF(AND($C13="",$D13=""),0,IF(AND($C13>$D13,K13>L13),'Tabla general'!$L$4,IF(AND($D13>$C13,L13>K13),'Tabla general'!$L$4,IF(AND($C13=$D13,K13=L13),'Tabla general'!$L$4,0))) + IF(AND($C13=K13,$D13=L13),'Tabla general'!$L$5,0)) -> 1 | N13: 1 | O13: 1 | P13: =IF(AND($C13="",$D13=""),0,IF(AND($C13>$D13,N13>O13),'Tabla general'!$L$4,IF(AND($D13>$C13,O13>N13),'Tabla general'!$L$4,IF(AND($C13=$D13,N13=O13),'Tabla general'!$L$4,0))) + IF(AND($C13=N13,$D13=O13),'Tabla general'!$L$5,0)) -> 0 | Q13: 2 | R13: 1 | S13: =IF(AND($C13="",$D13=""),0,IF(AND($C13>$D13,Q13>R13),'Tabla general'!$L$4,IF(AND($D13>$C13,R13>Q13),'Tabla general'!$L$4,IF(AND($C13=$D13,Q13=R13),'Tabla general'!$L$4,0))) + IF(AND($C13=Q13,$D13=R13),'Tabla general'!$L$5,0)) -> 1
A14: Republica de Irlanda | B14: Suecia | C14: 1 | D14: 1 | E14: 0 | F14: 1 | G14: =IF(AND($C14="",$D14=""),0,IF(AND($C14>$D14,E14>F14),'Tabla general'!$L$4,IF(AND($D14>$C14,F14>E14),'Tabla general'!$L$4,IF(AND($C14=$D14,E14=F14),'Tabla general'!$L$4,0))) + IF(AND($C14=E14,$D14=F14),'Tabla general'!$L$5,0)) -> 0 | H14: 0 | I14: 2 | J14: =IF(AND($C14="",$D14=""),0,IF(AND($C14>$D14,H14>I14),'Tabla general'!$L$4,IF(AND($D14>$C14,I14>H14),'Tabla general'!$L$4,IF(AND($C14=$D14,H14=I14),'Tabla general'!$L$4,0))) + IF(AND($C14=H14,$D14=I14),'Tabla general'!$L$5,0)) -> 0 | K14: 0 | L14: 2 | M14: =IF(AND($C14="",$D14=""),0,IF(AND($C14>$D14,K14>L14),'Tabla general'!$L$4,IF(AND($D14>$C14,L14>K14),'Tabla general'!$L$4,IF(AND($C14=$D14,K14=L14),'Tabla general'!$L$4,0))) + IF(AND($C14=K14,$D14=L14),'Tabla general'!$L$5,0)) -> 0 | N14: 0 | O14: 1 | P14: =IF(AND($C14="",$D14=""),0,IF(AND($C14>$D14,N14>O14),'Tabla general'!$L$4,IF(AND($D14>$C14,O14>N14),'Tabla general'!$L$4,IF(AND($C14=$D14,N14=O14),'Tabla general'!$L$4,0))) + IF(AND($C14=N14,$D14=O14),'Tabla general'!$L$5,0)) -> 0 | Q14: 1 | R14: 1 | S14: =IF(AND($C14="",$D14=""),0,IF(AND($C14>$D14,Q14>R14),'Tabla general'!$L$4,IF(AND($D14>$C14,R14>Q14),'Tabla general'!$L$4,IF(AND($C14=$D14,Q14=R14),'Tabla general'!$L$4,0))) + IF(AND($C14=Q14,$D14=R14),'Tabla general'!$L$5,0)) -> 2
A15: Belgica | B15: Italia | C15: 0 | D15: 2 | E15: 1 | F15: 1 | G15: =IF(AND($C15="",$D15=""),0,IF(AND($C15>$D15,E15>F15),'Tabla general'!$L$4,IF(AND($D15>$C15,F15>E15),'Tabla general'!$L$4,IF(AND($C15=$D15,E15=F15),'Tabla general'!$L$4,0))) + IF(AND($C15=E15,$D15=F15),'Tabla general'!$L$5,0)) -> 0 | H15: 1 | I15: 2 | J15: =IF(AND($C15="",$D15=""),0,IF(AND($C15>$D15,H15>I15),'Tabla general'!$L$4,IF(AND($D15>$C15,I15>H15),'Tabla general'!$L$4,IF(AND($C15=$D15,H15=I15),'Tabla general'!$L$4,0))) + IF(AND($C15=H15,$D15=I15),'Tabla general'!$L$5,0)) -> 1 | K15: 1 | L15: 1 | M15: =IF(AND($C15="",$D15=""),0,IF(AND($C15>$D15,K15>L15),'Tabla general'!$L$4,IF(AND($D15>$C15,L15>K15),'Tabla general'!$L$4,IF(AND($C15=$D15,K15=L15),'Tabla general'!$L$4,0))) + IF(AND($C15=K15,$D15=L15),'Tabla general'!$L$5,0)) -> 0 | N15: 2 | O15: 2 | P15: =IF(AND($C15="",$D15=""),0,IF(AND($C15>$D15,N15>O15),'Tabla general'!$L$4,IF(AND($D15>$C15,O15>N15),'Tabla general'!$L$4,IF(AND($C15=$D15,N15=O15),'Tabla general'!$L$4,0))) + IF(AND($C15=N15,$D15=O15),'Tabla general'!$L$5,0)) -> 0 | Q15: 1 | R15: 1 | S15: =IF(AND($C15="",$D15=""),0,IF(AND($C15>$D15,Q15>R15),'Tabla general'!$L$4,IF(AND($D15>$C15,R15>Q15),'Tabla general'!$L$4,IF(AND($C15=$D15,Q15=R15),'Tabla general'!$L$4,0))) + IF(AND($C15=Q15,$D15=R15),'Tabla general'!$L$5,0)) -> 0
A16: Austria | B16: Hungría | C16: 0 | D16: 2 | E16: 0 | F16: 0 | G16: =IF(AND($C16="",$D16=""),0,IF(AND($C16>$D16,E16>F16),'Tabla general'!$L$4,IF(AND($D16>$C16,F16>E16),'Tabla general'!$L$4,IF(AND($C16=$D16,E16=F16),'Tabla general'!$L$4,0))) + IF(AND($C16=E16,$D16=F16),'Tabla general'!$L$5,0)) -> 0 | H16: 0 | I16: 0 | J16: =IF(AND($C16="",$D16=""),0,IF(AND($C16>$D16,H16>I16),'Tabla general'!$L$4,IF(AND($D16>$C16,I16>H16),'Tabla general'!$L$4,IF(AND($C16=$D16,H16=I16),'Tabla general'!$L$4,0))) + IF(AND($C16=H16,$D16=I16),'Tabla general'!$L$5,0)) -> 0 | K16: 1 | L16: 0 | M16: =IF(AND($C16="",$D16=""),0,IF(AND($C16>$D16,K16>L16),'Tabla general'!$L$4,IF(AND($D16>$C16,L16>K16),'Tabla general'!$L$4,IF(AND($C16=$D16,K16=L16),'Tabla general'!$L$4,0))) + IF(AND($C16=K16,$D16=L16),'Tabla general'!$L$5,0)) -> 0 | N16: 0 | O16: 3 | P16: =IF(AND($C16="",$D16=""),0,IF(AND($C16>$D16,N16>O16),'Tabla general'!$L$4,IF(AND($D16>$C16,O16>N16),'Tabla general'!$L$4,IF(AND($C16=$D16,N16=O16),'Tabla general'!$L$4,0))) + IF(AND($C16=N16,$D16=O16),'Tabla general'!$L$5,0)) -> 1 | Q16: 2 | R16: 1 | S16: =IF(AND($C16="",$D16=""),0,IF(AND($C16>$D16,Q16>R16),'Tabla general'!$L$4,IF(AND($D16>$C16,R16>Q16),'Tabla general'!$L$4,IF(AND($C16=$D16,Q16=R16),'Tabla general'!$L$4,0))) + IF(AND($C16=Q16,$D16=R16),'Tabla general'!$L$5,0)) -> 0
A17: Portugal | B17: Islandia | C17: 1 | D17: 1 | E17: 2 | F17: 0 | G17: =IF(AND($C17="",$D17=""),0,IF(AND($C17>$D17,E17>F17),'Tabla general'!$L$4,IF(AND($D17>$C17,F17>E17),'Tabla general'!$L$4,IF(AND($C17=$D17,E17=F17),'Tabla general'!$L$4,0))) + IF(AND($C17=E17,$D17=F17),'Tabla general'!$L$5,0)) -> 0 | H17: 3 | I17: 0 | J17: =IF(AND($C17="",$D17=""),0,IF(AND($C17>$D17,H17>I17),'Tabla general'!$L$4,IF(AND($D17>$C17,I17>H17),'Tabla general'!$L$4,IF(AND($C17=$D17,H17=I17),'Tabla general'!$L$4,0))) + IF(AND($C17=H17,$D17=I17),'Tabla general'!$L$5,0)) -> 0 | K17: 4 | L17: 0 | M17: =IF(AND($C17="",$D17=""),0,IF(AND($C17>$D17,K17>L17),'Tabla general'!$L$4,IF(AND($D17>$C17,L17>K17),'Tabla general'!$L$4,IF(AND($C17=$D17,K17=L17),'Tabla general'!$L$4,0))) + IF(AND($C17=K17,$D17=L17),'Tabla general'!$L$5,0)) -> 0 | N17: 2 | O17: 0 | P17: =IF(AND($C17="",$D17=""),0,IF(AND($C17>$D17,N17>O17),'Tabla general'!$L$4,IF(AND($D17>$C17,O17>N17),'Tabla general'!$L$4,IF(AND($C17=$D17,N17=O17),'Tabla general'!$L$4,0))) + IF(AND($C17=N17,$D17=O17),'Tabla general'!$L$5,0)) -> 0 | Q17: 2 | R17: 0 | S17: =IF(AND($C17="",$D17=""),0,IF(AND($C17>$D17,Q17>R17),'Tabla general'!$L$4,IF(AND($D17>$C17,R17>Q17),'Tabla general'!$L$4,IF(AND($C17=$D17,Q17=R17),'Tabla general'!$L$4,0))) + IF(AND($C17=Q17,$D17=R17),'Tabla general'!$L$5,0)) -> 0
E18: Suma: | G18: =SUM(G$6:G$17,G$4) -> 11 | J18: =SUM(J$6:J$17,J$4) -> 9 | M18: =SUM(M$6:M$17,M$4) -> 5 | P18: =SUM(P$6:P$17,P$4) -> 5 | S18: =SUM(S$6:S$17,S$4) -> 9

Sheet Jornada 2 - Partidos
A1: Partidos del 15 al 18 de junio
B2: ids | E2: 1 | H2: 2 | K2: 3 | N2: 4 | Q2: 5
B3: Participantes | C3: Goles oficiales | E3: =VLOOKUP(E$2,[0]!participantes,2) -> Carlos Ruíz | G3: Puntos | H3: =VLOOKUP(H$2,[0]!participantes,2) -> Javier Ruíz | J3: Puntos | K3: =VLOOKUP(K$2,[0]!participantes,2) -> Jair Salomón | M3: Puntos | N3: =VLOOKUP(N$2,[0]!participantes,2) -> Kevin Salomón | P3: Puntos | Q3: =VLOOKUP(Q$2,[0]!participantes,2) -> Roberto Ruíz | S3: Puntos
B4: Goles de la semana | C4: =SUM(C6:D17) -> 25 | E4: =SUM(E6:F17) -> 31 | G4: =IF(E4=$C$4,'Tabla general'!$L$6,0) -> 0 | H4: =SUM(H6:I17) -> 28 | J4: =IF(H4=$C$4,'Tabla general'!$L$6,0) -> 0 | K4: 25 | M4: =IF(K4=$C$4,'Tabla general'!$L$6,0) -> 3 | N4: =SUM(N6:O17) -> 22 | P4: =IF(N4=$C$4,'Tabla general'!$L$6,0) -> 0 | Q4: =SUM(Q6:R17) -> 18 | S4: =IF(Q4=$C$4,'Tabla general'!$L$6,0) -> 0
A5: Partidos | C5: Marcadores oficiales | E5: Predicción | G5: Puntos | H5: Predicción | J5: Puntos | K5: Predicción | M5: Puntos | N5: Predicción | P5: Puntos | Q5: Predicción | S5: Puntos
A6: Rusia | B6: Eslovaquia | C6: 1 | D6: 2 | E6: 2 | F6: 1 | G6: =IF(AND($C6="",$D6=""),0,IF(AND($C6>$D6,E6>F6),'Tabla general'!$L$4,IF(AND($D6>$C6,F6>E6),'Tabla general'!$L$4,IF(AND($C6=$D6,E6=F6),'Tabla general'!$L$4,0))) + IF(AND($C6=E6,$D6=F6),'Tabla general'!$L$5,0)) -> 0 | H6: 2 | I6: 1 | J6: =IF(AND($C6="",$D6=""),0,IF(AND($C6>$D6,H6>I6),'Tabla general'!$L$4,IF(AND($D6>$C6,I6>H6),'Tabla general'!$L$4,IF(AND($C6=$D6,H6=I6),'Tabla general'!$L$4,0))) + IF(AND($C6=H6,$D6=I6),'Tabla general'!$L$5,0)) -> 0 | K6: 2 | L6: 1 | M6: =IF(AND($C6="",$D6=""),0,IF(AND($C6>$D6,K6>L6),'Tabla general'!$L$4,IF(AND($D6>$C6,L6>K6),'Tabla general'!$L$4,IF(AND($C6=$D6,K6=L6),'Tabla general'!$L$4,0))) + IF(AND($C6=K6,$D6=L6),'Tabla general'!$L$5,0)) -> 0 | N6: 0 | O6: 1 | P6: =IF(AND($C6="",$D6=""),0,IF(AND($C6>$D6,N6>O6),'Tabla general'!$L$4,IF(AND($D6>$C6,O6>N6),'Tabla general'!$L$4,IF(AND($C6=$D6,N6=O6),'Tabla general'!$L$4,0))) + IF(AND($C6=N6,$D6=O6),'Tabla general'!$L$5,0)) -> 1 | Q6: 1 | R6: 0 | S6: =IF(AND($C6="",$D6=""),0,IF(AND($C6>$D6,Q6>R6),'Tabla general'!$L$4,IF(AND($D6>$C6,R6>Q6),'Tabla general'!$L$4,IF(AND($C6=$D6,Q6=R6),'Tabla general'!$L$4,0))) + IF(AND($C6=Q6,$D6=R6),'Tabla general'!$L$5,0)) -> 0
A7: Rumania | B7: Suiza | C7: 1 | D7: 1 | E7: 1 | F7: 2 | G7: =IF(AND($C7="",$D7=""),0,IF(AND($C7>$D7,E7>F7),'Tabla general'!$L$4,IF(AND($D7>$C7,F7>E7),'Tabla general'!$L$4,IF(AND($C7=$D7,E7=F7),'Tabla general'!$L$4,0))) + IF(AND($C7=E7,$D7=F7),'Tabla general'!$L$5,0)) -> 0 | H7: 1 | I7: 1 | J7: =IF(AND($C7="",$D7=""),0,IF(AND($C7>$D7,H7>I7),'Tabla general'!$L$4,IF(AND($D7>$C7,I7>H7),'Tabla general'!$L$4,IF(AND($C7=$D7,H7=I7),'Tabla general'!$L$4,0))) + IF(AND($C7=H7,$D7=I7),'Tabla general'!$L$5,0)) -> 2 | K7: 0 | L7: 2 | M7: =IF(AND($C7="",$D7=""),0,IF(AND($C7>$D7,K7>L7),'Tabla general'!$L$4,IF(AND($D7>$C7,L7>K7),'Tabla general'!$L$4,IF(AND($C7=$D7,K7=L7),'Tabla general'!$L$4,0))) + IF(AND($C7=K7,$D7=L7),'Tabla general'!$L$5,0)) -> 0 | N7: 1 | O7: 1 | P7: =IF(AND($C7="",$D7=""),0,IF(AND($C7>$D7,N7>O7),'Tabla general'!$L$4,IF(AND($D7>$C7,O7>N7),'Tabla general'!$L$4,IF(AND($C7=$D7,N7=O7),'Tabla general'!$L$4,0))) + IF(AND($C7=N7,$D7=O7),'Tabla general'!$L$5,0)) -> 2 | Q7: 0 | R7: 1 | S7: =IF(AND($C7="",$D7=""),0,IF(AND($C7>$D7,Q7>R7),'Tabla general'!$L$4,IF(AND($D7>$C7,R7>Q7),'Tabla general'!$L$4,IF(AND($C7=$D7,Q7=R7),'Tabla general'!$L$4,0))) + IF(AND($C7=Q7,$D7=R7),'Tabla general'!$L$5,0)) -> 0
A8: Francia | B8: Albania | C8: 2 | D8: 0 | E8: 3 | F8: 1 | G8: =IF(AND($C8="",$D8=""),0,IF(AND($C8>$D8,E8>F8),'Tabla general'!$L$4,IF(AND($D8>$C8,F8>E8),'Tabla general'!$L$4,IF(AND($C8=$D8,E8=F8),'Tabla general'!$L$4,0))) + IF(AND($C8=E8,$D8=F8),'Tabla general'!$L$5,0)) -> 1 | H8: 2 | I8: 0 | J8: =IF(AND($C8="",$D8=""),0,IF(AND($C8>$D8,H8>I8),'Tabla general'!$L$4,IF(AND($D8>$C8,I8>H8),'Tabla general'!$L$4,IF(AND($C8=$D8,H8=I8),'Tabla general'!$L$4,0))) + IF(AND($C8=H8,$D8=I8),'Tabla general'!$L$5,0)) -> 2 | K8: 2 | L8: 0 | M8: =IF(AND($C8="",$D8=""),0,IF(AND($C8>$D8,K8>L8),'Tabla general'!$L$4,IF(AND($D8>$C8,L8>K8),'Tabla general'!$L$4,IF(AND($C8=$D8,K8=L8),'Tabla general'!$L$4,0))) + IF(AND($C8=K8,$D8=L8),'Tabla general'!$L$5,0)) -> 2 | N8: 2 | O8: 0 | P8: =IF(AND($C8="",$D8=""),0,IF(AND($C8>$D8,N8>O8),'Tabla general'!$L$4,IF(AND($D8>$C8,O8>N8),'Tabla general'!$L$4,IF(AND($C8=$D8,N8=O8),'Tabla general'!$L$4,0))) + IF(AND($C8=N8,$D8=O8),'Tabla general'!$L$5,0)) -> 2 | Q8: 1 | R8: 0 | S8: =IF(AND($C8="",$D8=""),0,IF(AND($C8>$D8,Q8>R8),'Tabla general'!$L$4,IF(AND($D8>$C8,R8>Q8),'Tabla general'!$L$4,IF(AND($C8=$D8,Q8=R8),'Tabla general'!$L$4,0))) + IF(AND($C8=Q8,$D8=R8),'Tabla general'!$L$5,0)) -> 1
A9: Inglaterra | B9: Gales | C9: 2 | D9: 1 | E9: 1 | F9: 1 | G9: =IF(AND($C9="",$D9=""),0,IF(AND($C9>$D9,E9>F9),'Tabla general'!$L$4,IF(AND($D9>$C9,F9>E9),'Tabla general'!$L$4,IF(AND($C9=$D9,E9=F9),'Tabla general'!$L$4,0))) + IF(AND($C9=E9,$D9=F9),'Tabla general'!$L$5,0)) -> 0 | H9: 2 | I9: 1 | J9: =IF(AND($C9="",$D9=""),0,IF(AND($C9>$D9,H9>I9),'Tabla general'!$L$4,IF(AND($D9>$C9,I9>H9),'Tabla general'!$L$4,IF(AND($C9=$D9,H9=I9),'Tabla general'!$L$4,0))) + IF(AND($C9=H9,$D9=I9),'Tabla general'!$L$5,0)) -> 2 | K9: 2 | L9: 1 | M9: =IF(AND($C9="",$D9=""),0,IF(AND($C9>$D9,K9>L9),'Tabla general'!$L$4,IF(AND($D9>$C9,L9>K9),'Tabla general'!$L$4,IF(AND($C9=$D9,K9=L9),'Tabla general'!$L$4,0))) + IF(AND($C9=K9,$D9=L9),'Tabla general'!$L$5,0)) -> 2 | N9: 2 | O9: 1 | P9: =IF(AND($C9="",$D9=""),0,IF(AND($C9>$D9,N9>O9),'Tabla general'!$L$4,IF(AND($D9>$C9,O9>N9),'Tabla general'!$L$4,IF(AND($C9=$D9,N9=O9),'Tabla general'!$L$4,0))) + IF(AND($C9=N9,$D9=O9),'Tabla general'!$L$5,0)) -> 2 | Q9: 1 | R9: 1 | S9: =IF(AND($C9="",$D9=""),0,IF(AND($C9>$D9,Q9>R9),'Tabla general'!$L$4,IF(AND($D9>$C9,R9>Q9),'Tabla general'!$L$4,IF(AND($C9=$D9,Q9=R9),'Tabla general'!$L$4,0))) + IF(AND($C9=Q9,$D9=R9),'Tabla general'!$L$5,0)) -> 0
A10: Ucrania | B10: Irlanda del norte | C10: 0 | D10: 2 | E10: 0 | F10: 1 | G10: =IF(AND($C10="",$D10=""),0,IF(AND($C10>$D10,E10>F10),'Tabla general'!$L$4,IF(AND($D10>$C10,F10>E10),'Tabla general'!$L$4,IF(AND($C10=$D10,E10=F10),'Tabla general'!$L$4,0))) + IF(AND($C10=E10,$D10=F10),'Tabla general'!$L$5,0)) -> 1 | H10: 2 | I10: 0 | J10: =IF(AND($C10="",$D10=""),0,IF(AND($C10>$D10,H10>I10),'Tabla general'!$L$4,IF(AND($D10>$C10,I10>H10),'Tabla general'!$L$4,IF(AND($C10=$D10,H10=I10),'Tabla general'!$L$4,0))) + IF(AND($C10=H10,$D10=I10),'Tabla general'!$L$5,0)) -> 0 | K10: 1 | L10: 2 | M10: =IF(AND($C10="",$D10=""),0,IF(AND($C10>$D10,K10>L10),'Tabla general'!$L$4,IF(AND($D10>$C10,L10>K10),'Tabla general'!$L$4,IF(AND($C10=$D10,K10=L10),'Tabla general'!$L$4,0))) + IF(AND($C10=K10,$D10=L10),'Tabla general'!$L$5,0)) -> 1 | N10: 0 | O10: 1 | P10: =IF(AND($C10="",$D10=""),0,IF(AND($C10>$D10,N10>O10),'Tabla general'!$L$4,IF(AND($D10>$C10,O10>N10),'Tabla general'!$L$4,IF(AND($C10=$D10,N10=O10),'Tabla general'!$L$4,0))) + IF(AND($C10=N10,$D10=O10),'Tabla general'!$L$5,0)) -> 1 | Q10: 0 | R10: 0 | S10: =IF(AND($C10="",$D10=""),0,IF(AND($C10>$D10,Q10>R10),'Tabla general'!$L$4,IF(AND($D10>$C10,R10>Q10),'Tabla general'!$L$4,IF(AND($C10=$D10,Q10=R10),'Tabla general'!$L$4,0))) + IF(AND($C10=Q10,$D10=R10),'Tabla general'!$L$5,0)) -> 0
A11: Alemania | B11: Polonia | C11: 0 | D11: 0 | E11: 2 | F11: 2 | G11: =IF(AND($C11="",$D11=""),0,IF(AND($C11>$D11,E11>F11),'Tabla general'!$L$4,IF(AND($D11>$C11,F11>E11),'Tabla general'!$L$4,IF(AND($C11=$D11,E11=F11),'Tabla general'!$L$4,0))) + IF(AND($C11=E11,$D11=F11),'Tabla general'!$L$5,0)) -> 1 | H11: 3 | I11: 1 | J11: =IF(AND($C11="",$D11=""),0,IF(AND($C11>$D11,H11>I11),'Tabla general'!$L$4,IF(AND($D11>$C11,I11>H11),'Tabla general'!$L$4,IF(AND($C11=$D11,H11=I11),'Tabla general'!$L$4,0))) + IF(AND($C11=H11,$D11=I11),'Tabla general'!$L$5,0)) -> 0 | K11: 2 | L11: 1 | M11: =IF(AND($C11="",$D11=""),0,IF(AND($C11>$D11,K11>L11),'Tabla general'!$L$4,IF(AND($D11>$C11,L11>K11),'Tabla general'!$L$4,IF(AND($C11=$D11,K11=L11),'Tabla general'!$L$4,0))) + IF(AND($C11=K11,$D11=L11),'Tabla general'!$L$5,0)) -> 0 | N11: 1 | O11: 0 | P11: =IF(AND($C11="",$D11=""),0,IF(AND($C11>$D11,N11>O11),'Tabla general'!$L$4,IF(AND($D11>$C11,O11>N11),'Tabla general'!$L$4,IF(AND($C11=$D11,N11=O11),'Tabla general'!$L$4,0))) + IF(AND($C11=N11,$D11=O11),'Tabla general'!$L$5,0)) -> 0 | Q11: 2 | R11: 0 | S11: =IF(AND($C11="",$D11=""),0,IF(AND($C11>$D11,Q11>R11),'Tabla general'!$L$4,IF(AND($D11>$C11,R11>Q11),'Tabla general'!$L$4,IF(AND($C11=$D11,Q11=R11),'Tabla general'!$L$4,0))) + IF(AND($C11=Q11,$D11=R11),'Tabla general'!$L$5,0)) -> 0
A12: Italia | B12: Suecia | C12: 1 | D12: 0 | E12: 1 | F12: 1 | G12: =IF(AND($C12="",$D12=""),0,IF(AND($C12>$D12,E12>F12),'Tabla general'!$L$4,IF(AND($D12>$C12,F12>E12),'Tabla general'!$L$4,IF(AND($C12=$D12,E12=F12),'Tabla general'!$L$4,0))) + IF(AND($C12=E12,$D12=F12),'Tabla general'!$L$5,0)) -> 0 | H12: 2 | I12: 0 | J12: =IF(AND($C12="",$D12=""),0,IF(AND($C12>$D12,H12>I12),'Tabla general'!$L$4,IF(AND($D12>$C12,I12>H12),'Tabla general'!$L$4,IF(AND($C12=$D12,H12=I12),'Tabla general'!$L$4,0))) + IF(AND($C12=H12,$D12=I12),'Tabla general'!$L$5,0)) -> 1 | K12: 2 | L12: 1 | M12: =IF(AND($C12="",$D12=""),0,IF(AND($C12>$D12,K12>L12),'Tabla general'!$L$4,IF(AND($D12>$C12,L12>K12),'Tabla general'!$L$4,IF(AND($C12=$D12,K12=L12),'Tabla general'!$L$4,0))) + IF(AND($C12=K12,$D12=L12),'Tabla general'!$L$5,0)) -> 1 | N12: 1 | O12: 0 | P12: =IF(AND($C12="",$D12=""),0,IF(AND($C12>$D12,N12>O12),'Tabla general'!$L$4,IF(AND($D12>$C12,O12>N12),'Tabla general'!$L$4,IF(AND($C12=$D12,N12=O12),'Tabla general'!$L$4,0))) + IF(AND($C12=N12,$D12=O12),'Tabla general'!$L$5,0)) -> 2 | Q12: 1 | R12: 0 | S12: =IF(AND($C12="",$D12=""),0,IF(AND($C12>$D12,Q12>R12),'Tabla general'!$L$4,IF(AND($D12>$C12,R12>Q12),'Tabla general'!$L$4,IF(AND($C12=$D12,Q12=R12),'Tabla general'!$L$4,0))) + IF(AND($C12=Q12,$D12=R12),'Tabla general'!$L$5,0)) -> 2
A13: Republica Checa | B13: Croacia | C13: 2 | D13: 2 | E13: 1 | F13: 2 | G13: =IF(AND($C13="",$D13=""),0,IF(AND($C13>$D13,E13>F13),'Tabla general'!$L$4,IF(AND($D13>$C13,F13>E13),'Tabla general'!$L$4,IF(AND($C13=$D13,E13=F13),'Tabla general'!$L$4,0))) + IF(AND($C13=E13,$D13=F13),'Tabla general'!$L$5,0)) -> 0 | H13: 1 | I13: 2 | J13: =IF(AND($C13="",$D13=""),0,IF(AND($C13>$D13,H13>I13),'Tabla general'!$L$4,IF(AND($D13>$C13,I13>H13),'Tabla general'!$L$4,IF(AND($C13=$D13,H13=I13),'Tabla general'!$L$4,0))) + IF(AND($C13=H13,$D13=I13),'Tabla general'!$L$5,0)) -> 0 | K13: 0 | L13: 2 | M13: =IF(AND($C13="",$D13=""),0,IF(AND($C13>$D13,K13>L13),'Tabla general'!$L$4,IF(AND($D13>$C13,L13>K13),'Tabla general'!$L$4,IF(AND($C13=$D13,K13=L13),'Tabla general'!$L$4,0))) + IF(AND($C13=K13,$D13=L13),'Tabla general'!$L$5,0)) -> 0 | N13: 2 | O13: 1 | P13: =IF(AND($C13="",$D13=""),0,IF(AND($C13>$D13,N13>O13),'Tabla general'!$L$4,IF(AND($D13>$C13,O13>N13),'Tabla general'!$L$4,IF(AND($C13=$D13,N13=O13),'Tabla general'!$L$4,0))) + IF(AND($C13=N13,$D13=O13),'Tabla general'!$L$5,0)) -> 0 | Q13: 1 | R13: 2 | S13: =IF(AND($C13="",$D13=""),0,IF(AND($C13>$D13,Q13>R13),'Tabla general'!$L$4,IF(AND($D13>$C13,R13>Q13),'Tabla general'!$L$4,IF(AND($C13=$D13,Q13=R13),'Tabla general'!$L$4,0))) + IF(AND($C13=Q13,$D13=R13),'Tabla general'!$L$5,0)) -> 0
A14: España | B14: Turquia | C14: 3 | D14: 0 | E14: 2 | F14: 1 | G14: =IF(AND($C14="",$D14=""),0,IF(AND($C14>$D14,E14>F14),'Tabla general'!$L$4,IF(AND($D14>$C14,F14>E14),'Tabla general'!$L$4,IF(AND($C14=$D14,E14=F14),'Tabla general'!$L$4,0))) + IF(AND($C14=E14,$D14=F14),'Tabla general'!$L$5,0)) -> 1 | H14: 2 | I14: 0 | J14: =IF(AND($C14="",$D14=""),0,IF(AND($C14>$D14,H14>I14),'Tabla general'!$L$4,IF(AND($D14>$C14,I14>H14),'Tabla general'!$L$4,IF(AND($C14=$D14,H14=I14),'Tabla general'!$L$4,0))) + IF(AND($C14=H14,$D14=I14),'Tabla general'!$L$5,0)) -> 1 | K14: 2 | L14: 0 | M14: =IF(AND($C14="",$D14=""),0,IF(AND($C14>$D14,K14>L14),'Tabla general'!$L$4,IF(AND($D14>$C14,L14>K14),'Tabla general'!$L$4,IF(AND($C14=$D14,K14=L14),'Tabla general'!$L$4,0))) + IF(AND($C14=K14,$D14=L14),'Tabla general'!$L$5,0)) -> 1 | N14: 2 | O14: 0 | P14: =IF(AND($C14="",$D14=""),0,IF(AND($C14>$D14,N14>O14),'Tabla general'!$L$4,IF(AND($D14>$C14,O14>N14),'Tabla general'!$L$4,IF(AND($C14=$D14,N14=O14),'Tabla general'!$L$4,0))) + IF(AND($C14=N14,$D14=O14),'Tabla general'!$L$5,0)) -> 1 | Q14: 1 | R14: 0 | S14: =IF(AND($C14="",$D14=""),0,IF(AND($C14>$D14,Q14>R14),'Tabla general'!$L$4,IF(AND($D14>$C14,R14>Q14),'Tabla general'!$L$4,IF(AND($C14=$D14,Q14=R14),'Tabla general'!$L$4,0))) + IF(AND($C14=Q14,$D14=R14),'Tabla general'!$L$5,0)) -> 1
A15: Belgica | B15: Republica de Irlanda | C15: 3 | D15: 0 | E15: 2 | F15: 0 | G15: =IF(AND($C15="",$D15=""),0,IF(AND($C15>$D15,E15>F15),'Tabla general'!$L$4,IF(AND($D15>$C15,F15>E15),'Tabla general'!$L$4,IF(AND($C15=$D15,E15=F15),'Tabla general'!$L$4,0))) + IF(AND($C15=E15,$D15=F15),'Tabla general'!$L$5,0)) -> 1 | H15: 2 | I15: 0 | J15: =IF(AND($C15="",$D15=""),0,IF(AND($C15>$D15,H15>I15),'Tabla general'!$L$4,IF(AND($D15>$C15,I15>H15),'Tabla general'!$L$4,IF(AND($C15=$D15,H15=I15),'Tabla general'!$L$4,0))) + IF(AND($C15=H15,$D15=I15),'Tabla general'!$L$5,0)) -> 1 | K15: 1 | L15: 0 | M15: =IF(AND($C15="",$D15=""),0,IF(AND($C15>$D15,K15>L15),'Tabla general'!$L$4,IF(AND($D15>$C15,L15>K15),'Tabla general'!$L$4,IF(AND($C15=$D15,K15=L15),'Tabla general'!$L$4,0))) + IF(AND($C15=K15,$D15=L15),'Tabla general'!$L$5,0)) -> 1 | N15: 1 | O15: 0 | P15: =IF(AND($C15="",$D15=""),0,IF(AND($C15>$D15,N15>O15),'Tabla general'!$L$4,IF(AND($D15>$C15,O15>N15),'Tabla general'!$L$4,IF(AND($C15=$D15,N15=O15),'Tabla general'!$L$4,0))) + IF(AND($C15=N15,$D15=O15),'Tabla general'!$L$5,0)) -> 1 | Q15: 2 | R15: 1 | S15: =IF(AND($C15="",$D15=""),0,IF(AND($C15>$D15,Q15>R15),'Tabla general'!$L$4,IF(AND($D15>$C15,R15>Q15),'Tabla general'!$L$4,IF(AND($C15=$D15,Q15=R15),'Tabla general'!$L$4,0))) + IF(AND($C15=Q15,$D15=R15),'Tabla general'!$L$5,0)) -> 1
A16: Islandia | B16: Hungria | C16: 1 | D16: 1 | E16: 0 | F16: 2 | G16: =IF(AND($C16="",$D16=""),0,IF(AND($C16>$D16,E16>F16),'Tabla general'!$L$4,IF(AND($D16>$C16,F16>E16),'Tabla general'!$L$4,IF(AND($C16=$D16,E16=F16),'Tabla general'!$L$4,0))) + IF(AND($C16=E16,$D16=F16),'Tabla general'!$L$5,0)) -> 0 | H16: 0 | I16: 1 | J16: =IF(AND($C16="",$D16=""),0,IF(AND($C16>$D16,H16>I16),'Tabla general'!$L$4,IF(AND($D16>$C16,I16>H16),'Tabla general'!$L$4,IF(AND($C16=$D16,H16=I16),'Tabla general'!$L$4,0))) + IF(AND($C16=H16,$D16=I16),'Tabla general'!$L$5,0)) -> 0 | K16: 0 | L16: 1 | M16: =IF(AND($C16="",$D16=""),0,IF(AND($C16>$D16,K16>L16),'Tabla general'!$L$4,IF(AND($D16>$C16,L16>K16),'Tabla general'!$L$4,IF(AND($C16=$D16,K16=L16),'Tabla general'!$L$4,0))) + IF(AND($C16=K16,$D16=L16),'Tabla general'!$L$5,0)) -> 0 | N16: 1 | O16: 1 | P16: =IF(AND($C16="",$D16=""),0,IF(AND($C16>$D16,N16>O16),'Tabla general'!$L$4,IF(AND($D16>$C16,O16>N16),'Tabla general'!$L$4,IF(AND($C16=$D16,N16=O16),'Tabla general'!$L$4,0))) + IF(AND($C16=N16,$D16=O16),'Tabla general'!$L$5,0)) -> 2 | Q16: 1 | R16: 1 | S16: =IF(AND($C16="",$D16=""),0,IF(AND($C16>$D16,Q16>R16),'Tabla general'!$L$4,IF(AND($D16>$C16,R16>Q16),'Tabla general'!$L$4,IF(AND($C16=$D16,Q16=R16),'Tabla general'!$L$4,0))) + IF(AND($C16=Q16,$D16=R16),'Tabla general'!$L$5,0)) -> 2
A17: Portugal | B17: Austria | C17: 0 | D17: 0 | E17: 2 | F17: 0 | G17: =IF(AND($C17="",$D17=""),0,IF(AND($C17>$D17,E17>F17),'Tabla general'!$L$4,IF(AND($D17>$C17,F17>E17),'Tabla general'!$L$4,IF(AND($C17=$D17,E17=F17),'Tabla general'!$L$4,0))) + IF(AND($C17=E17,$D17=F17),'Tabla general'!$L$5,0)) -> 0 | H17: 2 | I17: 0 | J17: =IF(AND($C17="",$D17=""),0,IF(AND($C17>$D17,H17>I17),'Tabla general'!$L$4,IF(AND($D17>$C17,I17>H17),'Tabla general'!$L$4,IF(AND($C17=$D17,H17=I17),'Tabla general'!$L$4,0))) + IF(AND($C17=H17,$D17=I17),'Tabla general'!$L$5,0)) -> 0 | K17: 3 | L17: 0 | M17: =IF(AND($C17="",$D17=""),0,IF(AND($C17>$D17,K17>L17),'Tabla general'!$L$4,IF(AND($D17>$C17,L17>K17),'Tabla general'!$L$4,IF(AND($C17=$D17,K17=L17),'Tabla general'!$L$4,0))) + IF(AND($C17=K17,$D17=L17),'Tabla general'!$L$5,0)) -> 0 | N17: 2 | O17: 1 | P17: =IF(AND($C17="",$D17=""),0,IF(AND($C17>$D17,N17>O17),'Tabla general'!$L$4,IF(AND($D17>$C17,O17>N17),'Tabla general'!$L$4,IF(AND($C17=$D17,N17=O17),'Tabla general'!$L$4,0))) + IF(AND($C17=N17,$D17=O17),'Tabla general'!$L$5,0)) -> 0 | Q17: 1 | R17: 0 | S17: =IF(AND($C17="",$D17=""),0,IF(AND($C17>$D17,Q17>R17),'Tabla general'!$L$4,IF(AND($D17>$C17,R17>Q17),'Tabla general'!$L$4,IF(AND($C17=$D17,Q17=R17),'Tabla general'!$L$4,0))) + IF(AND($C17=Q17,$D17=R17),'Tabla general'!$L$5,0)) -> 0
E18: Suma: | G18: =SUM(G$6:G$17,G$4) -> 5 | J18: =SUM(J$6:J$17,J$4) -> 9 | M18: =SUM(M$6:M$17,M$4) -> 11 | P18: =SUM(P$6:P$17,P$4) -> 14 | S18: =SUM(S$6:S$17,S$4) -> 7

Sheet Jornada 3 - Partidos
A1: Partidos del 19 al 22 de junio
B2: ids | E2: 1 | H2: 2 | K2: 3 | N2: 4 | Q2: 5
B3: Participantes | C3: Goles oficiales | E3: =VLOOKUP(E$2,[0]!participantes,2) -> Carlos Ruíz | G3: Puntos | H3: =VLOOKUP(H$2,[0]!participantes,2) -> Javier Ruíz | J3: Puntos | K3: =VLOOKUP(K$2,[0]!participantes,2) -> Jair Salomón | M3: Puntos | N3: =VLOOKUP(N$2,[0]!participantes,2) -> Kevin Salomón | P3: Puntos | Q3: =VLOOKUP(Q$2,[0]!participantes,2) -> Roberto Ruíz | S3: Puntos
B4: Goles de la semana | C4: =SUM(C6:D17) -> 22 | E4: =SUM(E6:F17) -> 15 | G4: =IF(E4=$C$4,'Tabla general'!$L$6,0) -> 0 | H4: =SUM(H6:I17) -> 34 | J4: =IF(H4=$C$4,'Tabla general'!$L$6,0) -> 0 | K4: =SUM(K6:L17) -> 28 | M4: =IF(K4=$C$4,'Tabla general'!$L$6,0) -> 0 | N4: =SUM(N6:O17) -> 26 | P4: =IF(N4=$C$4,'Tabla general'!$L$6,0) -> 0 | Q4: =SUM(Q6:R17) -> 24 | S4: =IF(Q4=$C$4,'Tabla general'!$L$6,0) -> 0
A5: Partidos | C5: Marcadores oficiales | E5: Predicción | G5: Puntos | H5: Predicción | J5: Puntos | K5: Predicción | M5: Puntos | N5: Predicción | P5: Puntos | Q5: Predicción | S5: Puntos
A6: Suiza | B6: Francia | C6: 0 | D6: 0 | E6: 0 | F6: 2 | G6: =IF(AND($C6="",$D6=""),0,IF(AND($C6>$D6,E6>F6),'Tabla general'!$L$4,IF(AND($D6>$C6,F6>E6),'Tabla general'!$L$4,IF(AND($C6=$D6,E6=F6),'Tabla general'!$L$4,0))) + IF(AND($C6=E6,$D6=F6),'Tabla general'!$L$5,0)) -> 0 | H6: 1 | I6: 2 | J6: =IF(AND($C6="",$D6=""),0,IF(AND($C6>$D6,H6>I6),'Tabla general'!$L$4,IF(AND($D6>$C6,I6>H6),'Tabla general'!$L$4,IF(AND($C6=$D6,H6=I6),'Tabla general'!$L$4,0))) + IF(AND($C6=H6,$D6=I6),'Tabla general'!$L$5,0)) -> 0 | K6: 1 | L6: 1 | M6: =IF(AND($C6="",$D6=""),0,IF(AND($C6>$D6,K6>L6),'Tabla general'!$L$4,IF(AND($D6>$C6,L6>K6),'Tabla general'!$L$4,IF(AND($C6=$D6,K6=L6),'Tabla general'!$L$4,0))) + IF(AND($C6=K6,$D6=L6),'Tabla general'!$L$5,0)) -> 1 | N6: 1 | O6: 1 | P6: =IF(AND($C6="",$D6=""),0,IF(AND($C6>$D6,N6>O6),'Tabla general'!$L$4,IF(AND($D6>$C6,O6>N6),'Tabla general'!$L$4,IF(AND($C6=$D6,N6=O6),'Tabla general'!$L$4,0))) + IF(AND($C6=N6,$D6=O6),'Tabla general'!$L$5,0)) -> 1 | Q6: 1 | R6: 2 | S6: =IF(AND($C6="",$D6=""),0,IF(AND($C6>$D6,Q6>R6),'Tabla general'!$L$4,IF(AND($D6>$C6,R6>Q6),'Tabla general'!$L$4,IF(AND($C6=$D6,Q6=R6),'Tabla general'!$L$4,0))) + IF(AND($C6=Q6,$D6=R6),'Tabla general'!$L$5,0)) -> 0
A7: Rumania | B7: Albania | C7: 0 | D7: 1 | E7: 0 | F7: 0 | G7: =IF(AND($C7="",$D7=""),0,IF(AND($C7>$D7,E7>F7),'Tabla general'!$L$4,IF(AND($D7>$C7,F7>E7),'Tabla general'!$L$4,IF(AND($C7=$D7,E7=F7),'Tabla general'!$L$4,0))) + IF(AND($C7=E7,$D7=F7),'Tabla general'!$L$5,0)) -> 0 | H7: 2 | I7: 1 | J7: =IF(AND($C7="",$D7=""),0,IF(AND($C7>$D7,H7>I7),'Tabla general'!$L$4,IF(AND($D7>$C7,I7>H7),'Tabla general'!$L$4,IF(AND($C7=$D7,H7=I7),'Tabla general'!$L$4,0))) + IF(AND($C7=H7,$D7=I7),'Tabla general'!$L$5,0)) -> 0 | K7: 1 | L7: 2 | M7: =IF(AND($C7="",$D7=""),0,IF(AND($C7>$D7,K7>L7),'Tabla general'!$L$4,IF(AND($D7>$C7,L7>K7),'Tabla general'!$L$4,IF(AND($C7=$D7,K7=L7),'Tabla general'!$L$4,0))) + IF(AND($C7=K7,$D7=L7),'Tabla general'!$L$5,0)) -> 1 | N7: 2 | O7: 0 | P7: =IF(AND($C7="",$D7=""),0,IF(AND($C7>$D7,N7>O7),'Tabla general'!$L$4,IF(AND($D7>$C7,O7>N7),'Tabla general'!$L$4,IF(AND($C7=$D7,N7=O7),'Tabla general'!$L$4,0))) + IF(AND($C7=N7,$D7=O7),'Tabla general'!$L$5,0)) -> 0 | Q7: 1 | R7: 0 | S7: =IF(AND($C7="",$D7=""),0,IF(AND($C7>$D7,Q7>R7),'Tabla general'!$L$4,IF(AND($D7>$C7,R7>Q7),'Tabla general'!$L$4,IF(AND($C7=$D7,Q7=R7),'Tabla general'!$L$4,0))) + IF(AND($C7=Q7,$D7=R7),'Tabla general'!$L$5,0)) -> 0
A8: Eslovaquia | B8: Inglaterra | C8: 0 | D8: 0 | E8: 0 | F8: 1 | G8: =IF(AND($C8="",$D8=""),0,IF(AND($C8>$D8,E8>F8),'Tabla general'!$L$4,IF(AND($D8>$C8,F8>E8),'Tabla general'!$L$4,IF(AND($C8=$D8,E8=F8),'Tabla general'!$L$4,0))) + IF(AND($C8=E8,$D8=F8),'Tabla general'!$L$5,0)) -> 0 | H8: 1 | I8: 1 | J8: =IF(AND($C8="",$D8=""),0,IF(AND($C8>$D8,H8>I8),'Tabla general'!$L$4,IF(AND($D8>$C8,I8>H8),'Tabla general'!$L$4,IF(AND($C8=$D8,H8=I8),'Tabla general'!$L$4,0))) + IF(AND($C8=H8,$D8=I8),'Tabla general'!$L$5,0)) -> 1 | K8: 0 | L8: 1 | M8: =IF(AND($C8="",$D8=""),0,IF(AND($C8>$D8,K8>L8),'Tabla general'!$L$4,IF(AND($D8>$C8,L8>K8),'Tabla general'!$L$4,IF(AND($C8=$D8,K8=L8),'Tabla general'!$L$4,0))) + IF(AND($C8=K8,$D8=L8),'Tabla general'!$L$5,0)) -> 0 | N8: 1 | O8: 2 | P8: =IF(AND($C8="",$D8=""),0,IF(AND($C8>$D8,N8>O8),'Tabla general'!$L$4,IF(AND($D8>$C8,O8>N8),'Tabla general'!$L$4,IF(AND($C8=$D8,N8=O8),'Tabla general'!$L$4,0))) + IF(AND($C8=N8,$D8=O8),'Tabla general'!$L$5,0)) -> 0 | Q8: 1 | R8: 2 | S8: =IF(AND($C8="",$D8=""),0,IF(AND($C8>$D8,Q8>R8),'Tabla general'!$L$4,IF(AND($D8>$C8,R8>Q8),'Tabla general'!$L$4,IF(AND($C8=$D8,Q8=R8),'Tabla general'!$L$4,0))) + IF(AND($C8=Q8,$D8=R8),'Tabla general'!$L$5,0)) -> 0
A9: Rusia | B9: Gales | C9: 0 | D9: 3 | E9: 0 | F9: 1 | G9: =IF(AND($C9="",$D9=""),0,IF(AND($C9>$D9,E9>F9),'Tabla general'!$L$4,IF(AND($D9>$C9,F9>E9),'Tabla general'!$L$4,IF(AND($C9=$D9,E9=F9),'Tabla general'!$L$4,0))) + IF(AND($C9=E9,$D9=F9),'Tabla general'!$L$5,0)) -> 1 | H9: 1 | I9: 1 | J9: =IF(AND($C9="",$D9=""),0,IF(AND($C9>$D9,H9>I9),'Tabla general'!$L$4,IF(AND($D9>$C9,I9>H9),'Tabla general'!$L$4,IF(AND($C9=$D9,H9=I9),'Tabla general'!$L$4,0))) + IF(AND($C9=H9,$D9=I9),'Tabla general'!$L$5,0)) -> 0 | K9: 0 | L9: 2 | M9: =IF(AND($C9="",$D9=""),0,IF(AND($C9>$D9,K9>L9),'Tabla general'!$L$4,IF(AND($D9>$C9,L9>K9),'Tabla general'!$L$4,IF(AND($C9=$D9,K9=L9),'Tabla general'!$L$4,0))) + IF(AND($C9=K9,$D9=L9),'Tabla general'!$L$5,0)) -> 1 | N9: 0 | O9: 2 | P9: =IF(AND($C9="",$D9=""),0,IF(AND($C9>$D9,N9>O9),'Tabla general'!$L$4,IF(AND($D9>$C9,O9>N9),'Tabla general'!$L$4,IF(AND($C9=$D9,N9=O9),'Tabla general'!$L$4,0))) + IF(AND($C9=N9,$D9=O9),'Tabla general'!$L$5,0)) -> 1 | Q9: 0 | R9: 1 | S9: =IF(AND($C9="",$D9=""),0,IF(AND($C9>$D9,Q9>R9),'Tabla general'!$L$4,IF(AND($D9>$C9,R9>Q9),'Tabla general'!$L$4,IF(AND($C9=$D9,Q9=R9),'Tabla general'!$L$4,0))) + IF(AND($C9=Q9,$D9=R9),'Tabla general'!$L$5,0)) -> 1
A10: Irlanda del norte | B10: Alemania | C10: 0 | D10: 1 | E10: 0 | F10: 2 | G10: =IF(AND($C10="",$D10=""),0,IF(AND($C10>$D10,E10>F10),'Tabla general'!$L$4,IF(AND($D10>$C10,F10>E10),'Tabla general'!$L$4,IF(AND($C10=$D10,E10=F10),'Tabla general'!$L$4,0))) + IF(AND($C10=E10,$D10=F10),'Tabla general'!$L$5,0)) -> 1 | H10: 1 | I10: 3 | J10: =IF(AND($C10="",$D10=""),0,IF(AND($C10>$D10,H10>I10),'Tabla general'!$L$4,IF(AND($D10>$C10,I10>H10),'Tabla general'!$L$4,IF(AND($C10=$D10,H10=I10),'Tabla general'!$L$4,0))) + IF(AND($C10=H10,$D10=I10),'Tabla general'!$L$5,0)) -> 1 | K10: 0 | L10: 3 | M10: =IF(AND($C10="",$D10=""),0,IF(AND($C10>$D10,K10>L10),'Tabla general'!$L$4,IF(AND($D10>$C10,L10>K10),'Tabla general'!$L$4,IF(AND($C10=$D10,K10=L10),'Tabla general'!$L$4,0))) + IF(AND($C10=K10,$D10=L10),'Tabla general'!$L$5,0)) -> 1 | N10: 0 | O10: 2 | P10: =IF(AND($C10="",$D10=""),0,IF(AND($C10>$D10,N10>O10),'Tabla general'!$L$4,IF(AND($D10>$C10,O10>N10),'Tabla general'!$L$4,IF(AND($C10=$D10,N10=O10),'Tabla general'!$L$4,0))) + IF(AND($C10=N10,$D10=O10),'Tabla general'!$L$5,0)) -> 1 | Q10: 1 | R10: 2 | S10: =IF(AND($C10="",$D10=""),0,IF(AND($C10>$D10,Q10>R10),'Tabla general'!$L$4,IF(AND($D10>$C10,R10>Q10),'Tabla general'!$L$4,IF(AND($C10=$D10,Q10=R10),'Tabla general'!$L$4,0))) + IF(AND($C10=Q10,$D10=R10),'Tabla general'!$L$5,0)) -> 1
A11: Ucrania | B11: Polonia | C11: 0 | D11: 1 | E11: 0 | F11: 1 | G11: =IF(AND($C11="",$D11=""),0,IF(AND($C11>$D11,E11>F11),'Tabla general'!$L$4,IF(AND($D11>$C11,F11>E11),'Tabla general'!$L$4,IF(AND($C11=$D11,E11=F11),'Tabla general'!$L$4,0))) + IF(AND($C11=E11,$D11=F11),'Tabla general'!$L$5,0)) -> 2 | H11: 0 | I11: 2 | J11: =IF(AND($C11="",$D11=""),0,IF(AND($C11>$D11,H11>I11),'Tabla general'!$L$4,IF(AND($D11>$C11,I11>H11),'Tabla general'!$L$4,IF(AND($C11=$D11,H11=I11),'Tabla general'!$L$4,0))) + IF(AND($C11=H11,$D11=I11),'Tabla general'!$L$5,0)) -> 1 | K11: 0 | L11: 1 | M11: =IF(AND($C11="",$D11=""),0,IF(AND($C11>$D11,K11>L11),'Tabla general'!$L$4,IF(AND($D11>$C11,L11>K11),'Tabla general'!$L$4,IF(AND($C11=$D11,K11=L11),'Tabla general'!$L$4,0))) + IF(AND($C11=K11,$D11=L11),'Tabla general'!$L$5,0)) -> 2 | N11: 0 | O11: 2 | P11: =IF(AND($C11="",$D11=""),0,IF(AND($C11>$D11,N11>O11),'Tabla general'!$L$4,IF(AND($D11>$C11,O11>N11),'Tabla general'!$L$4,IF(AND($C11=$D11,N11=O11),'Tabla general'!$L$4,0))) + IF(AND($C11=N11,$D11=O11),'Tabla general'!$L$5,0)) -> 1 | Q11: 0 | R11: 1 | S11: =IF(AND($C11="",$D11=""),0,IF(AND($C11>$D11,Q11>R11),'Tabla general'!$L$4,IF(AND($D11>$C11,R11>Q11),'Tabla general'!$L$4,IF(AND($C11=$D11,Q11=R11),'Tabla general'!$L$4,0))) + IF(AND($C11=Q11,$D11=R11),'Tabla general'!$L$5,0)) -> 2
A12: Croacia | B12: España | C12: 2 | D12: 1 | E12: 0 | F12: 2 | G12: =IF(AND($C12="",$D12=""),0,IF(AND($C12>$D12,E12>F12),'Tabla general'!$L$4,IF(AND($D12>$C12,F12>E12),'Tabla general'!$L$4,IF(AND($C12=$D12,E12=F12),'Tabla general'!$L$4,0))) + IF(AND($C12=E12,$D12=F12),'Tabla general'!$L$5,0)) -> 0 | H12: 1 | I12: 2 | J12: =IF(AND($C12="",$D12=""),0,IF(AND($C12>$D12,H12>I12),'Tabla general'!$L$4,IF(AND($D12>$C12,I12>H12),'Tabla general'!$L$4,IF(AND($C12=$D12,H12=I12),'Tabla general'!$L$4,0))) + IF(AND($C12=H12,$D12=I12),'Tabla general'!$L$5,0)) -> 0 | K12: 1 | L12: 2 | M12: =IF(AND($C12="",$D12=""),0,IF(AND($C12>$D12,K12>L12),'Tabla general'!$L$4,IF(AND($D12>$C12,L12>K12),'Tabla general'!$L$4,IF(AND($C12=$D12,K12=L12),'Tabla general'!$L$4,0))) + IF(AND($C12=K12,$D12=L12),'Tabla general'!$L$5,0)) -> 0 | N12: 1 | O12: 1 | P12: =IF(AND($C12="",$D12=""),0,IF(AND($C12>$D12,N12>O12),'Tabla general'!$L$4,IF(AND($D12>$C12,O12>N12),'Tabla general'!$L$4,IF(AND($C12=$D12,N12=O12),'Tabla general'!$L$4,0))) + IF(AND($C12=N12,$D12=O12),'Tabla general'!$L$5,0)) -> 0 | Q12: 1 | R12: 1 | S12: =IF(AND($C12="",$D12=""),0,IF(AND($C12>$D12,Q12>R12),'Tabla general'!$L$4,IF(AND($D12>$C12,R12>Q12),'Tabla general'!$L$4,IF(AND($C12=$D12,Q12=R12),'Tabla general'!$L$4,0))) + IF(AND($C12=Q12,$D12=R12),'Tabla general'!$L$5,0)) -> 0
A13: Republica Checa | B13: Turquia | C13: 0 | D13: 2 | E13: 1 | F13: 0 | G13: =IF(AND($C13="",$D13=""),0,IF(AND($C13>$D13,E13>F13),'Tabla general'!$L$4,IF(AND($D13>$C13,F13>E13),'Tabla general'!$L$4,IF(AND($C13=$D13,E13=F13),'Tabla general'!$L$4,0))) + IF(AND($C13=E13,$D13=F13),'Tabla general'!$L$5,0)) -> 0 | H13: 1 | I13: 2 | J13: =IF(AND($C13="",$D13=""),0,IF(AND($C13>$D13,H13>I13),'Tabla general'!$L$4,IF(AND($D13>$C13,I13>H13),'Tabla general'!$L$4,IF(AND($C13=$D13,H13=I13),'Tabla general'!$L$4,0))) + IF(AND($C13=H13,$D13=I13),'Tabla general'!$L$5,0)) -> 1 | K13: 2 | L13: 0 | M13: =IF(AND($C13="",$D13=""),0,IF(AND($C13>$D13,K13>L13),'Tabla general'!$L$4,IF(AND($D13>$C13,L13>K13),'Tabla general'!$L$4,IF(AND($C13=$D13,K13=L13),'Tabla general'!$L$4,0))) + IF(AND($C13=K13,$D13=L13),'Tabla general'!$L$5,0)) -> 0 | N13: 2 | O13: 0 | P13: =IF(AND($C13="",$D13=""),0,IF(AND($C13>$D13,N13>O13),'Tabla general'!$L$4,IF(AND($D13>$C13,O13>N13),'Tabla general'!$L$4,IF(AND($C13=$D13,N13=O13),'Tabla general'!$L$4,0))) + IF(AND($C13=N13,$D13=O13),'Tabla general'!$L$5,0)) -> 0 | Q13: 2 | R13: 0 | S13: =IF(AND($C13="",$D13=""),0,IF(AND($C13>$D13,Q13>R13),'Tabla general'!$L$4,IF(AND($D13>$C13,R13>Q13),'Tabla general'!$L$4,IF(AND($C13=$D13,Q13=R13),'Tabla general'!$L$4,0))) + IF(AND($C13=Q13,$D13=R13),'Tabla general'!$L$5,0)) -> 0
A14: Islandia | B14: Austria | C14: 2 | D14: 1 | E14: 0 | F14: 0 | G14: =IF(AND($C14="",$D14=""),0,IF(AND($C14>$D14,E14>F14),'Tabla general'!$L$4,IF(AND($D14>$C14,F14>E14),'Tabla general'!$L$4,IF(AND($C14=$D14,E14=F14),'Tabla general'!$L$4,0))) + IF(AND($C14=E14,$D14=F14),'Tabla general'!$L$5,0)) -> 0 | H14: 2 | I14: 1 | J14: =IF(AND($C14="",$D14=""),0,IF(AND($C14>$D14,H14>I14),'Tabla general'!$L$4,IF(AND($D14>$C14,I14>H14),'Tabla general'!$L$4,IF(AND($C14=$D14,H14=I14),'Tabla general'!$L$4,0))) + IF(AND($C14=H14,$D14=I14),'Tabla general'!$L$5,0)) -> 2 | K14: 2 | L14: 1 | M14: =IF(AND($C14="",$D14=""),0,IF(AND($C14>$D14,K14>L14),'Tabla general'!$L$4,IF(AND($D14>$C14,L14>K14),'Tabla general'!$L$4,IF(AND($C14=$D14,K14=L14),'Tabla general'!$L$4,0))) + IF(AND($C14=K14,$D14=L14),'Tabla general'!$L$5,0)) -> 2 | N14: 1 | O14: 1 | P14: =IF(AND($C14="",$D14=""),0,IF(AND($C14>$D14,N14>O14),'Tabla general'!$L$4,IF(AND($D14>$C14,O14>N14),'Tabla general'!$L$4,IF(AND($C14=$D14,N14=O14),'Tabla general'!$L$4,0))) + IF(AND($C14=N14,$D14=O14),'Tabla general'!$L$5,0)) -> 0 | Q14: 1 | R14: 0 | S14: =IF(AND($C14="",$D14=""),0,IF(AND($C14>$D14,Q14>R14),'Tabla general'!$L$4,IF(AND($D14>$C14,R14>Q14),'Tabla general'!$L$4,IF(AND($C14=$D14,Q14=R14),'Tabla general'!$L$4,0))) + IF(AND($C14=Q14,$D14=R14),'Tabla general'!$L$5,0)) -> 1
A15: Hungria | B15: Portugal | C15: 3 | D15: 3 | E15: 0 | F15: 1 | G15: =IF(AND($C15="",$D15=""),0,IF(AND($C15>$D15,E15>F15),'Tabla general'!$L$4,IF(AND($D15>$C15,F15>E15),'Tabla general'!$L$4,IF(AND($C15=$D15,E15=F15),'Tabla general'!$L$4,0))) + IF(AND($C15=E15,$D15=F15),'Tabla general'!$L$5,0)) -> 0 | H15: 0 | I15: 2 | J15: =IF(AND($C15="",$D15=""),0,IF(AND($C15>$D15,H15>I15),'Tabla general'!$L$4,IF(AND($D15>$C15,I15>H15),'Tabla general'!$L$4,IF(AND($C15=$D15,H15=I15),'Tabla general'!$L$4,0))) + IF(AND($C15=H15,$D15=I15),'Tabla general'!$L$5,0)) -> 0 | K15: 0 | L15: 2 | M15: =IF(AND($C15="",$D15=""),0,IF(AND($C15>$D15,K15>L15),'Tabla general'!$L$4,IF(AND($D15>$C15,L15>K15),'Tabla general'!$L$4,IF(AND($C15=$D15,K15=L15),'Tabla general'!$L$4,0))) + IF(AND($C15=K15,$D15=L15),'Tabla general'!$L$5,0)) -> 0 | N15: 1 | O15: 2 | P15: =IF(AND($C15="",$D15=""),0,IF(AND($C15>$D15,N15>O15),'Tabla general'!$L$4,IF(AND($D15>$C15,O15>N15),'Tabla general'!$L$4,IF(AND($C15=$D15,N15=O15),'Tabla general'!$L$4,0))) + IF(AND($C15=N15,$D15=O15),'Tabla general'!$L$5,0)) -> 0 | Q15: 1 | R15: 1 | S15: =IF(AND($C15="",$D15=""),0,IF(AND($C15>$D15,Q15>R15),'Tabla general'!$L$4,IF(AND($D15>$C15,R15>Q15),'Tabla general'!$L$4,IF(AND($C15=$D15,Q15=R15),'Tabla general'!$L$4,0))) + IF(AND($C15=Q15,$D15=R15),'Tabla general'!$L$5,0)) -> 1
A16: Suecia | B16: Belgica | C16: 0 | D16: 1 | E16: 1 | F16: 2 | G16: =IF(AND($C16="",$D16=""),0,IF(AND($C16>$D16,E16>F16),'Tabla general'!$L$4,IF(AND($D16>$C16,F16>E16),'Tabla general'!$L$4,IF(AND($C16=$D16,E16=F16),'Tabla general'!$L$4,0))) + IF(AND($C16=E16,$D16=F16),'Tabla general'!$L$5,0)) -> 1 | H16: 1 | I16: 3 | J16: =IF(AND($C16="",$D16=""),0,IF(AND($C16>$D16,H16>I16),'Tabla general'!$L$4,IF(AND($D16>$C16,I16>H16),'Tabla general'!$L$4,IF(AND($C16=$D16,H16=I16),'Tabla general'!$L$4,0))) + IF(AND($C16=H16,$D16=I16),'Tabla general'!$L$5,0)) -> 1 | K16: 2 | L16: 2 | M16: =IF(AND($C16="",$D16=""),0,IF(AND($C16>$D16,K16>L16),'Tabla general'!$L$4,IF(AND($D16>$C16,L16>K16),'Tabla general'!$L$4,IF(AND($C16=$D16,K16=L16),'Tabla general'!$L$4,0))) + IF(AND($C16=K16,$D16=L16),'Tabla general'!$L$5,0)) -> 0 | N16: 1 | O16: 2 | P16: =IF(AND($C16="",$D16=""),0,IF(AND($C16>$D16,N16>O16),'Tabla general'!$L$4,IF(AND($D16>$C16,O16>N16),'Tabla general'!$L$4,IF(AND($C16=$D16,N16=O16),'Tabla general'!$L$4,0))) + IF(AND($C16=N16,$D16=O16),'Tabla general'!$L$5,0)) -> 1 | Q16: 1 | R16: 2 | S16: =IF(AND($C16="",$D16=""),0,IF(AND($C16>$D16,Q16>R16),'Tabla general'!$L$4,IF(AND($D16>$C16,R16>Q16),'Tabla general'!$L$4,IF(AND($C16=$D16,Q16=R16),'Tabla general'!$L$4,0))) + IF(AND($C16=Q16,$D16=R16),'Tabla general'!$L$5,0)) -> 1
A17: Italia | B17: Republica de Irlanda | C17: 0 | D17: 1 | E17: 1 | F17: 0 | G17: =IF(AND($C17="",$D17=""),0,IF(AND($C17>$D17,E17>F17),'Tabla general'!$L$4,IF(AND($D17>$C17,F17>E17),'Tabla general'!$L$4,IF(AND($C17=$D17,E17=F17),'Tabla general'!$L$4,0))) + IF(AND($C17=E17,$D17=F17),'Tabla general'!$L$5,0)) -> 0 | H17: 2 | I17: 1 | J17: =IF(AND($C17="",$D17=""),0,IF(AND($C17>$D17,H17>I17),'Tabla general'!$L$4,IF(AND($D17>$C17,I17>H17),'Tabla general'!$L$4,IF(AND($C17=$D17,H17=I17),'Tabla general'!$L$4,0))) + IF(AND($C17=H17,$D17=I17),'Tabla general'!$L$5,0)) -> 0 | K17: 2 | L17: 0 | M17: =IF(AND($C17="",$D17=""),0,IF(AND($C17>$D17,K17>L17),'Tabla general'!$L$4,IF(AND($D17>$C17,L17>K17),'Tabla general'!$L$4,IF(AND($C17=$D17,K17=L17),'Tabla general'!$L$4,0))) + IF(AND($C17=K17,$D17=L17),'Tabla general'!$L$5,0)) -> 0 | N17: 1 | O17: 0 | P17: =IF(AND($C17="",$D17=""),0,IF(AND($C17>$D17,N17>O17),'Tabla general'!$L$4,IF(AND($D17>$C17,O17>N17),'Tabla general'!$L$4,IF(AND($C17=$D17,N17=O17),'Tabla general'!$L$4,0))) + IF(AND($C17=N17,$D17=O17),'Tabla general'!$L$5,0)) -> 0 | Q17: 2 | R17: 0 | S17: =IF(AND($C17="",$D17=""),0,IF(AND($C17>$D17,Q17>R17),'Tabla general'!$L$4,IF(AND($D17>$C17,R17>Q17),'Tabla general'!$L$4,IF(AND($C17=$D17,Q17=R17),'Tabla general'!$L$4,0))) + IF(AND($C17=Q17,$D17=R17),'Tabla general'!$L$5,0)) -> 0
E18: Suma: | G18: =SUM(G$6:G$17,G$4) -> 5 | J18: =SUM(J$6:J$17,J$4) -> 7 | M18: =SUM(M$6:M$17,M$4) -> 8 | P18: =SUM(P$6:P$17,P$4) -> 5 | S18: =SUM(S$6:S$17,S$4) -> 7

Sheet Octavos - Partidos
A1: Partidos del 25 al 27 de junio (Octavos de final)
B2: ids | E2: 1 | H2: 2 | K2: 3 | N2: 4 | Q2: 5
B3: Participantes | C3: Goles oficiales | E3: =VLOOKUP(E$2,[0]!participantes,2) -> Carlos Ruíz | G3: Puntos | H3: =VLOOKUP(H$2,[0]!participantes,2) -> Javier Ruíz | J3: Puntos | K3: =VLOOKUP(K$2,[0]!participantes,2) -> Jair Salomón | M3: Puntos | N3: =VLOOKUP(N$2,[0]!participantes,2) -> Kevin Salomón | P3: Puntos | Q3: =VLOOKUP(Q$2,[0]!participantes,2) -> Roberto Ruíz | S3: Puntos
B4: Goles de la semana | C4: =SUM(C6:D13) -> 19 | E4: =SUM(E6:F13) -> 19 | G4: =IF(E4=$C$4,'Tabla general'!$L$6,0) -> 3 | H4: =SUM(H6:I13) -> 20 | J4: =IF(H4=$C$4,'Tabla general'!$L$6,0) -> 0 | K4: =SUM(K6:L13) -> 23 | M4: =IF(K4=$C$4,'Tabla general'!$L$6,0) -> 0 | N4: =SUM(N6:O13) -> 15 | P4: =IF(N4=$C$4,'Tabla general'!$L$6,0) -> 0 | Q4: =SUM(Q6:R13) -> 19 | S4: =IF(Q4=$C$4,'Tabla general'!$L$6,0) -> 3
A5: Partidos | C5: Marcadores oficiales | E5: Predicción | G5: Puntos | H5: Predicción | J5: Puntos | K5: Predicción | M5: Puntos | N5: Predicción | P5: Puntos | Q5: Predicción | S5: Puntos
A6: Suiza | B6: Polonia | C6: 1 | D6: 1 | E6: 0 | F6: 2 | G6: =IF(AND($C6="",$D6=""),0,IF(AND($C6>$D6,E6>F6),'Tabla general'!$L$4,IF(AND($D6>$C6,F6>E6),'Tabla general'!$L$4,IF(AND($C6=$D6,E6=F6),'Tabla general'!$L$4,0))) + IF(AND($C6=E6,$D6=F6),'Tabla general'!$L$5,0)) -> 0 | H6: 1 | I6: 2 | J6: =IF(AND($C6="",$D6=""),0,IF(AND($C6>$D6,H6>I6),'Tabla general'!$L$4,IF(AND($D6>$C6,I6>H6),'Tabla general'!$L$4,IF(AND($C6=$D6,H6=I6),'Tabla general'!$L$4,0))) + IF(AND($C6=H6,$D6=I6),'Tabla general'!$L$5,0)) -> 0 | K6: 1 | L6: 2 | M6: =IF(AND($C6="",$D6=""),0,IF(AND($C6>$D6,K6>L6),'Tabla general'!$L$4,IF(AND($D6>$C6,L6>K6),'Tabla general'!$L$4,IF(AND($C6=$D6,K6=L6),'Tabla general'!$L$4,0))) + IF(AND($C6=K6,$D6=L6),'Tabla general'!$L$5,0)) -> 0 | N6: 1 | O6: 1 | P6: =IF(AND($C6="",$D6=""),0,IF(AND($C6>$D6,N6>O6),'Tabla general'!$L$4,IF(AND($D6>$C6,O6>N6),'Tabla general'!$L$4,IF(AND($C6=$D6,N6=O6),'Tabla general'!$L$4,0))) + IF(AND($C6=N6,$D6=O6),'Tabla general'!$L$5,0)) -> 2 | Q6: 1 | R6: 1 | S6: =IF(AND($C6="",$D6=""),0,IF(AND($C6>$D6,Q6>R6),'Tabla general'!$L$4,IF(AND($D6>$C6,R6>Q6),'Tabla general'!$L$4,IF(AND($C6=$D6,Q6=R6),'Tabla general'!$L$4,0))) + IF(AND($C6=Q6,$D6=R6),'Tabla general'!$L$5,0)) -> 2
A7: Gales | B7: Irlanda del Norte | C7: 1 | D7: 0 | E7: 2 | F7: 1 | G7: =IF(AND($C7="",$D7=""),0,IF(AND($C7>$D7,E7>F7),'Tabla general'!$L$4,IF(AND($D7>$C7,F7>E7),'Tabla general'!$L$4,IF(AND($C7=$D7,E7=F7),'Tabla general'!$L$4,0))) + IF(AND($C7=E7,$D7=F7),'Tabla general'!$L$5,0)) -> 1 | H7: 1 | I7: 0 | J7: =IF(AND($C7="",$D7=""),0,IF(AND($C7>$D7,H7>I7),'Tabla general'!$L$4,IF(AND($D7>$C7,I7>H7),'Tabla general'!$L$4,IF(AND($C7=$D7,H7=I7),'Tabla general'!$L$4,0))) + IF(AND($C7=H7,$D7=I7),'Tabla general'!$L$5,0)) -> 2 | K7: 2 | L7: 0 | M7: =IF(AND($C7="",$D7=""),0,IF(AND($C7>$D7,K7>L7),'Tabla general'!$L$4,IF(AND($D7>$C7,L7>K7),'Tabla general'!$L$4,IF(AND($C7=$D7,K7=L7),'Tabla general'!$L$4,0))) + IF(AND($C7=K7,$D7=L7),'Tabla general'!$L$5,0)) -> 1 | N7: 2 | O7: 0 | P7: =IF(AND($C7="",$D7=""),0,IF(AND($C7>$D7,N7>O7),'Tabla general'!$L$4,IF(AND($D7>$C7,O7>N7),'Tabla general'!$L$4,IF(AND($C7=$D7,N7=O7),'Tabla general'!$L$4,0))) + IF(AND($C7=N7,$D7=O7),'Tabla general'!$L$5,0)) -> 1 | Q7: 2 | R7: 1 | S7: =IF(AND($C7="",$D7=""),0,IF(AND($C7>$D7,Q7>R7),'Tabla general'!$L$4,IF(AND($D7>$C7,R7>Q7),'Tabla general'!$L$4,IF(AND($C7=$D7,Q7=R7),'Tabla general'!$L$4,0))) + IF(AND($C7=Q7,$D7=R7),'Tabla general'!$L$5,0)) -> 1
A8: Croacia | B8: Portugal | C8: 0 | D8: 1 | E8: 1 | F8: 2 | G8: =IF(AND($C8="",$D8=""),0,IF(AND($C8>$D8,E8>F8),'Tabla general'!$L$4,IF(AND($D8>$C8,F8>E8),'Tabla general'!$L$4,IF(AND($C8=$D8,E8=F8),'Tabla general'!$L$4,0))) + IF(AND($C8=E8,$D8=F8),'Tabla general'!$L$5,0)) -> 1 | H8: 1 | I8: 1 | J8: =IF(AND($C8="",$D8=""),0,IF(AND($C8>$D8,H8>I8),'Tabla general'!$L$4,IF(AND($D8>$C8,I8>H8),'Tabla general'!$L$4,IF(AND($C8=$D8,H8=I8),'Tabla general'!$L$4,0))) + IF(AND($C8=H8,$D8=I8),'Tabla general'!$L$5,0)) -> 0 | K8: 2 | L8: 2 | M8: =IF(AND($C8="",$D8=""),0,IF(AND($C8>$D8,K8>L8),'Tabla general'!$L$4,IF(AND($D8>$C8,L8>K8),'Tabla general'!$L$4,IF(AND($C8=$D8,K8=L8),'Tabla general'!$L$4,0))) + IF(AND($C8=K8,$D8=L8),'Tabla general'!$L$5,0)) -> 0 | N8: 2 | O8: 1 | P8: =IF(AND($C8="",$D8=""),0,IF(AND($C8>$D8,N8>O8),'Tabla general'!$L$4,IF(AND($D8>$C8,O8>N8),'Tabla general'!$L$4,IF(AND($C8=$D8,N8=O8),'Tabla general'!$L$4,0))) + IF(AND($C8=N8,$D8=O8),'Tabla general'!$L$5,0)) -> 0 | Q8: 2 | R8: 1 | S8: =IF(AND($C8="",$D8=""),0,IF(AND($C8>$D8,Q8>R8),'Tabla general'!$L$4,IF(AND($D8>$C8,R8>Q8),'Tabla general'!$L$4,IF(AND($C8=$D8,Q8=R8),'Tabla general'!$L$4,0))) + IF(AND($C8=Q8,$D8=R8),'Tabla general'!$L$5,0)) -> 0
