Workbook
Name participantes: [1]Participantes!$A$2:$D$101
Name participantes: Participantes!$A$2:$D$101
Name PronosticosSem1: 'Sem 1 - Partidos'!$G$2:$AZ$30
Name PronosticosSem2: 'Sem 2 - Partidos'!$G$2:$AZ$31
Name PronosticosSem3: 'Sem 3 - Partidos'!$G$2:$AZ$14
Name PronosticosSem4: 'Sem 4 - Partidos'!$G$2:$AZ$14

Sheet Bases
A1: Rusia 2018 | B1: Torneo entre amigos
B2: Participación en el torneo basado en las quinielas tradicionales
A3: Torneos: | B3: Todos los partidos de Rusia 2018 (hasta la final)
A4: Bases: | B4: Esta competencia toma como base las quinielas tracionales. Consiste en lo siguiente: 1.- El participante debe pronosticar por cada partido el resultado que espera se dará en el mismo, indicando los goles anotados por los equipos. 2.- El torneo se dividirá en 4 semanas. Sem 1 - 14 al 21 de junio. (23 partidos) Sem 2 - 22 al 28 de junio. (25 partidos) Sem 3 - 30 de junio al 3 de julio. (8 partidos) Sem 4 - 6 al 15 de julio. (8 partidos) 3.- Por cada semana se jugarán tres puntos adicionales por lo que serán un total de 12 puntos, apoyando con esto a generar desempates. 4.- Existe tres ganadores de la bolsa 1°, 2° y 3° lugar; donde: 1° Se lleva el 70% de la bolsa 2° Se lleva el 20% de la bolsa 3° Se lleva el 10% de la bolsa Por lo que los 3 participantes con mayor cantidad de puntos serán acreedores a los premios. En caso de empate se dividirá el premio en partes iguales bajo las condiciones que se marcan en la sección de "Los Ganadores". 5.- Participante que no suba sus pronósticos antes de iniciar la semana en turno (hay una fecha limite marcada para cada semana) contabilizará 0 puntos y no podrá cargar sus resultados una vez pasada la hora límite. 6.- Los resultados que se toman como oficiales son los goles dentro de los 120 min máximo de cada partido, es decir que el resultado del partido hasta el final de los tiempos extra es el oficial y por medio del cual se ganan los puntos. Los goles por la definición por penales (después de los 120 min.) NO CUENTAN, para ninguno de los puntos.
A5: Puntos: (¿Cómo se obtienen?) | B5: La obtención de los puntos es de la siguiente forma: 1.- Se obtendrá un punto por pronosticar correctamente al ganador o empate por cualquier resultado que se presente. Ejemplo: España 2 - 1 Francia. En caso de ganar España por este u otro resultado se genera el punto. 2.- Se obtiene un segundo punto por cada partido, cuando se pronostique correctamente el resultado del mismo, es decir, siguiendo con el ejemplo anterior, en caso de la victoria española por 2 a 1 se generará el punto. 3.- El participante pronosticará la cantidad de goles que se anotarán por cada semana, de forma independiente a los indicados en los resultados pronosticados de los partidos o en su caso la plantilla sumará automáticamente la cantidad de goles que pronosticó. El participante decide si quedarse con la suma o cambiar por otra estimación escribiendolo sobre la celda de goles. Si la cuota de goles oficiales efectivamente se cumple el participante genera 3 puntos por acertar los goles de la semana.
A6: Ganador: | B6: El partidipante con mayor número de puntos obtenidos se lleva el 1° lugar. El participante que sigue al 1° lugar en mayor cantidad de puntos se lleva el 2° lugar. El participante que sigue al 2° lugar en mayor cantidad de puntos se lleva el 3° lugar. En caso de empates a 1° lugar: Si son 2 persona empatadas, el premio de 1° y 2° se suman; el resultado se divide entre el número de participantes empatados por partes iguales. Ya no habría premio a segundo, solo al tercer lugar. Si son 3 o más personas empatadas, el premio de 1°, 2° y 3° se suman; el resultado se divide entre el número de participantes empatados por partes iguales. Ya no habría premio a segundo y tercer lugar. En caso de empates a 2° lugar: Si son 2 persona empatadas, el premio de 2° y 3° se suman; el resultado se divide entre el número de participantes empatados por partes iguales. Se entrega premio al 1° y no hay premio de 3° lugar. Si son 3 o más personas empatadas, el premio de 2° y 3° se suman; el resultado se divide entre el número de participantes empatados por partes iguales. Se entrega premio al 1° y no hay premio de 3° lugar. En caso de empates a 3° lugar: Se entrega premio al 1° y 2° lugar. El premio de 3° lugar se divide entre el número de participantes empatados por partes iguales.
A7: Costo: | B7: 300
A8: Cierre de incripción: | B8: Miercoles 13 de junio a las 6 pm.

Sheet Participantes
A1: id | B1: Nombre | C1: Iniciales | D1: Lugar | E1: Pagado | H1: Premios | I1: % | J1: $
A2: 1 | B2: Noemi Padilla | C2: NP | D2: INFOTEC CDMX | F2: 300 | H2: 1° Lugar | I2: 0.7 | J2: =$F$22*I2 -> 2730
A3: 2 | B3: Fabricio Ruíz | C3: FR | D3: INFOTEC AGS | F3: 300 | H3: 2° Lugar | I3: 0.2 | J3: =$F$22*I3 -> 780
A4: 3 | B4: Adrian Molina | C4: AM | D4: INFOTEC AGS | F4: 300 | H4: 3° Lugar | I4: 0.1 | J4: =$F$22*I4 -> 390
A5: 4 | B5: Ezequiel Manzo | C5: EM | D5: EX INFOTEC AGS | F5: 300 | I5: Suma: | J5: =SUM(J2:J4) -> 3900
A6: 5 | B6: Ricardo Guerra | C6: RG | D6: INFOTEC AGS | F6: 300
A7: 6 | B7: Mario | C7: M | D7: INFOTEC AGS | F7: 300
A8: 7 | B8: Alejandro Cruz | C8: AC | D8: INFOTEC CDMX | F8: 300
A9: 8 | B9: Antonio Lopez | C9: AL | D9: INFOTEC AGS | F9: 300
A10: 9 | B10: Christian | C10: C | D10: INFOTEC AGS | F10: 300
A11: 10 | B11: Kevin Salomón | C11: KS | D11: INFOTEC AGS | F11: 300
A12: 11 | B12: Emmanuel | C12: E | D12: INFOTEC AGS | F12: 300
A13: 12 | B13: Miguel Villafuerte | C13: MV | D13: EX INFOTEC AGS | F13: 300
A14: 13 | B14: David Perez | C14: DP | D14: INFOTEC AGS | F14: 300
A15: 14 | B15: - | C15: - | D15: -
A16: 15 | B16: - | C16: - | D16: -
A17: 16 | B17: - | C17: - | D17: -
A18: 17 | B18: - | C18: - | D18: -
A19: 18 | B19: - | C19: - | D19: -
A20: 19 | B20: - | C20: - | D20: -
A21: 20 | B21: - | C21: - | D21: -
E22: Bolsa: | F22: =SUM(F2:F21) -> 3900

Sheet Tabla general
B1: Tabla General
A3: id | B3: Participante | C3: Puntos | E3: Lugar | K3: Puntos
A4: 1 | B4: =VLOOKUP($A4,[0]!participantes,2) -> Noemi Padilla | C4: =SUM(HLOOKUP(A4,PronosticosSem1,29,FALSE), HLOOKUP(A4,PronosticosSem2,30,FALSE), HLOOKUP(A4,PronosticosSem3,13,FALSE), HLOOKUP(A4,PronosticosSem4,13,FALSE)) -> 0 | K4: Partido | L4: 1
A5: 2 | B5: =VLOOKUP($A5,[0]!participantes,2) -> Fabricio Ruíz | C5: =SUM(HLOOKUP(A5,PronosticosSem1,29,FALSE), HLOOKUP(A5,PronosticosSem2,30,FALSE), HLOOKUP(A5,PronosticosSem3,13,FALSE), HLOOKUP(A5,PronosticosSem4,13,FALSE)) -> 0 | K5: Resultado | L5: 1
A6: 3 | B6: =VLOOKUP($A6,[0]!participantes,2) -> Adrian Molina | C6: =SUM(HLOOKUP(A6,PronosticosSem1,29,FALSE), HLOOKUP(A6,PronosticosSem2,30,FALSE), HLOOKUP(A6,PronosticosSem3,13,FALSE), HLOOKUP(A6,PronosticosSem4,13,FALSE)) -> 0 | K6: Goles | L6: 3
A7: 4 | B7: =VLOOKUP($A7,[0]!participantes,2) -> Ezequiel Manzo | C7: =SUM(HLOOKUP(A7,PronosticosSem1,29,FALSE), HLOOKUP(A7,PronosticosSem2,30,FALSE), HLOOKUP(A7,PronosticosSem3,13,FALSE), HLOOKUP(A7,PronosticosSem4,13,FALSE)) -> 0
A8: 5 | B8: =VLOOKUP($A8,[0]!participantes,2) -> Ricardo Guerra | C8: =SUM(HLOOKUP(A8,PronosticosSem1,29,FALSE), HLOOKUP(A8,PronosticosSem2,30,FALSE), HLOOKUP(A8,PronosticosSem3,13,FALSE), HLOOKUP(A8,PronosticosSem4,13,FALSE)) -> 0
A9: 6 | B9: =VLOOKUP($A9,[0]!participantes,2) -> Mario | C9: =SUM(HLOOKUP(A9,PronosticosSem1,29,FALSE), HLOOKUP(A9,PronosticosSem2,30,FALSE), HLOOKUP(A9,PronosticosSem3,13,FALSE), HLOOKUP(A9,PronosticosSem4,13,FALSE)) -> 0
A10: 7 | B10: =VLOOKUP($A10,[0]!participantes,2) -> Alejandro Cruz | C10: =SUM(HLOOKUP(A10,PronosticosSem1,29,FALSE), HLOOKUP(A10,PronosticosSem2,30,FALSE), HLOOKUP(A10,PronosticosSem3,13,FALSE), HLOOKUP(A10,PronosticosSem4,13,FALSE)) -> 0
A11: 8 | B11: =VLOOKUP($A11,[0]!participantes,2) -> Antonio Lopez | C11: =SUM(HLOOKUP(A11,PronosticosSem1,29,FALSE), HLOOKUP(A11,PronosticosSem2,30,FALSE), HLOOKUP(A11,PronosticosSem3,13,FALSE), HLOOKUP(A11,PronosticosSem4,13,FALSE)) -> 0
A12: 9 | B12: =VLOOKUP($A12,[0]!participantes,2) -> Christian | C12: =SUM(HLOOKUP(A12,PronosticosSem1,29,FALSE), HLOOKUP(A12,PronosticosSem2,30,FALSE), HLOOKUP(A12,PronosticosSem3,13,FALSE), HLOOKUP(A12,PronosticosSem4,13,FALSE)) -> 0
A13: 10 | B13: =VLOOKUP($A13,[0]!participantes,2) -> Kevin Salomón | C13: =SUM(HLOOKUP(A13,PronosticosSem1,29,FALSE), HLOOKUP(A13,PronosticosSem2,30,FALSE), HLOOKUP(A13,PronosticosSem3,13,FALSE), HLOOKUP(A13,PronosticosSem4,13,FALSE)) -> 0
A14: 11 | B14: =VLOOKUP($A14,[0]!participantes,2) -> Emmanuel | C14: =SUM(HLOOKUP(A14,PronosticosSem1,29,FALSE), HLOOKUP(A14,PronosticosSem2,30,FALSE), HLOOKUP(A14,PronosticosSem3,13,FALSE), HLOOKUP(A14,PronosticosSem4,13,FALSE)) -> 0
A15: 12 | B15: =VLOOKUP($A15,[0]!participantes,2) -> Miguel Villafuerte | C15: =SUM(HLOOKUP(A15,PronosticosSem1,29,FALSE), HLOOKUP(A15,PronosticosSem2,30,FALSE), HLOOKUP(A15,PronosticosSem3,13,FALSE), HLOOKUP(A15,PronosticosSem4,13,FALSE)) -> 0
A16: 13 | B16: =VLOOKUP($A16,[0]!participantes,2) -> David Perez | C16: =SUM(HLOOKUP(A16,PronosticosSem1,29,FALSE), HLOOKUP(A16,PronosticosSem2,30,FALSE), HLOOKUP(A16,PronosticosSem3,13,FALSE), HLOOKUP(A16,PronosticosSem4,13,FALSE)) -> 0
A17: 14 | B17: =VLOOKUP($A17,[0]!participantes,2) -> - | C17: =SUM(HLOOKUP(A17,PronosticosSem1,29,FALSE), HLOOKUP(A17,PronosticosSem2,30,FALSE), HLOOKUP(A17,PronosticosSem3,13,FALSE), HLOOKUP(A17,PronosticosSem4,13,FALSE)) -> 0
A18: 15 | B18: =VLOOKUP($A18,[0]!participantes,2) -> - | C18: =SUM(HLOOKUP(A18,PronosticosSem1,29,FALSE), HLOOKUP(A18,PronosticosSem2,30,FALSE), HLOOKUP(A18,PronosticosSem3,13,FALSE), HLOOKUP(A18,PronosticosSem4,13,FALSE)) -> 0
A19: 16 | B19: =VLOOKUP($A19,[0]!participantes,2) -> -
A20: 17 | B20: =VLOOKUP($A20,[0]!participantes,2) -> -
A21: 18 | B21: =VLOOKUP($A21,[0]!participantes,2) -> -
A22: 19 | B22: =VLOOKUP($A22,[0]!participantes,2) -> -
A23: 20 | B23: =VLOOKUP($A23,[0]!participantes,2) -> -

Sheet Sem 1 - Partidos
A1: Primeros 23 partidos de la FASE DE GRUPOS del 14 al 21 de junio. Limite para subir tu pronóstico 13 de junio 6:00 PM
B2: ids | G2: 1 | J2: 2 | M2: 3 | P2: 4 | S2: 5 | V2: 6 | W2: 7 | AB2: 7 | AE2: 8 | AH2: 9 | AK2: 10 | AN2: 11 | AQ2: 12 | AT2: 13 | AW2: 14 | AZ2: 15
B3: Participantes | C3: Goles oficiales | E3: =VLOOKUP(G$2,[0]!participantes,2) -> Noemi Padilla | G3: Puntos | H3: =VLOOKUP(J$2,[0]!participantes,2) -> Fabricio Ruíz | J3: Puntos | K3: =VLOOKUP(M$2,[0]!participantes,2) -> Adrian Molina | M3: Puntos | N3: =VLOOKUP(P$2,[0]!participantes,2) -> Ezequiel Manzo | P3: Puntos | Q3: =VLOOKUP(S$2,[0]!participantes,2) -> Ricardo Guerra | S3: Puntos | T3: =VLOOKUP(V$2,[0]!participantes,2) -> Mario | V3: Puntos | W3: =VLOOKUP(W$2,[0]!participantes,2) -> Alejandro Cruz | Y3: Puntos | Z3: =VLOOKUP(AB$2,[0]!participantes,2) -> Alejandro Cruz | AB3: Puntos | AC3: =VLOOKUP(AE$2,[0]!participantes,2) -> Antonio Lopez | AE3: Puntos | AF3: =VLOOKUP(AH$2,[0]!participantes,2) -> Christian | AH3: Puntos | AI3: =VLOOKUP(AK$2,[0]!participantes,2) -> Kevin Salomón | AK3: Puntos | AL3: =VLOOKUP(AN$2,[0]!participantes,2) -> Emmanuel | AN3: Puntos | AO3: =VLOOKUP(AQ$2,[0]!participantes,2) -> Miguel Villafuerte | AQ3: Puntos | AR3: =VLOOKUP(AT$2,[0]!participantes,2) -> David Perez | AT3: Puntos | AU3: =VLOOKUP(AW$2,[0]!participantes,2) -> - | AW3: Puntos | AX3: =VLOOKUP(AZ$2,[0]!participantes,2) -> - | AZ3: Puntos
B4: Goles de la semana | E4: =SUM(E6:F29) -> 0 | G4: =IF($C$4<>"",IF(E4=$C$4,'Tabla general'!$L$6,0), 0) -> 0 | H4: =SUM(H6:I29) -> 0 | J4: =IF($C$4<>"",IF(H4=$C$4,'Tabla general'!$L$6,0), 0) -> 0 | K4: =SUM(K6:L29) -> 0 | M4: =IF($C$4<>"",IF(K4=$C$4,'Tabla general'!$L$6,0), 0) -> 0 | N4: =SUM(N6:O29) -> 0 | P4: =IF($C$4<>"",IF(N4=$C$4,'Tabla general'!$L$6,0), 0) -> 0 | Q4: =SUM(Q6:R29) -> 0 | S4: =IF($C$4<>"",IF(Q4=$C$4,'Tabla general'!$L$6,0), 0) -> 0 | T4: =SUM(T6:U29) -> 0 | V4: =IF($C$4<>"",IF(T4=$C$4,'Tabla general'!$L$6,0), 0) -> 0 | W4: =SUM(W6:X29) -> 0 | Y4: =IF($C$4<>"",IF(W4=$C$4,'Tabla general'!$L$6,0), 0) -> 0 | Z4: =SUM(Z6:AA29) -> 0 | AB4: =IF($C$4<>"",IF(Z4=$C$4,'Tabla general'!$L$6,0), 0) -> 0 | AC4: =SUM(AC6:AD29) -> 0 | AE4: =IF($C$4<>"",IF(AC4=$C$4,'Tabla general'!$L$6,0), 0) -> 0 | AF4: =SUM(AF6:AG29) -> 0 | AH4: =IF($C$4<>"",IF(AF4=$C$4,'Tabla general'!$L$6,0), 0) -> 0 | AI4: =SUM(AI6:AJ29) -> 0 | AK4: =IF($C$4<>"",IF(AI4=$C$4,'Tabla general'!$L$6,0), 0) -> 0 | AL4: =SUM(AL6:AM29) -> 0 | AN4: =IF($C$4<>"",IF(AL4=$C$4,'Tabla general'!$L$6,0), 0) -> 0 | AO4: =SUM(AO6:AP29) -> 0 | AQ4: =IF($C$4<>"",IF(AO4=$C$4,'Tabla general'!$L$6,0), 0) -> 0 | AR4: =SUM(AR6:AS29) -> 0 | AT4: =IF($C$4<>"",IF(AR4=$C$4,'Tabla general'!$L$6,0), 0) -> 0 | AU4: =SUM(AU6:AV29) -> 0 | AW4: =IF($C$4<>"",IF(AU4=$C$4,'Tabla general'!$L$6,0), 0) -> 0 | AX4: =SUM(AX6:AY29) -> 0 | AZ4: =IF($C$4<>"",IF(AX4=$C$4,'Tabla general'!$L$6,0), 0) -> 0
A5: Partidos | C5: Marcadores oficiales | E5: Predicción | G5: Puntos | H5: Predicción | J5: Puntos | K5: Predicción | M5: Puntos | N5: Predicción | P5: Puntos | Q5: Predicción | S5: Puntos | T5: Predicción | V5: Puntos | W5: Predicción | Y5: Puntos | Z5: Predicción | AB5: Puntos | AC5: Predicción | AE5: Puntos | AF5: Predicción | AH5: Puntos | AI5: Predicción | AK5: Puntos | AL5: Predicción | AN5: Puntos | AO5: Predicción | AQ5: Puntos | AR5: Predicción | AT5: Puntos | AU5: Predicción | AW5: Puntos | AX5: Predicción | AZ5: Puntos
A6: Rusia | B6: Arabia Saudí | G6: =IF(AND($C6="",$D6=""),0,IF(AND($C6>$D6,E6>F6),'Tabla general'!$L$4,IF(AND($D6>$C6,F6>E6),'Tabla general'!$L$4,IF(AND($C6=$D6,E6=F6),'Tabla general'!$L$4,0))) + IF(AND($C6=E6,$D6=F6),'Tabla general'!$L$5,0)) -> 0 | J6: =IF(AND($C6="",$D6=""),0,IF(AND($C6>$D6,H6>I6),'Tabla general'!$L$4,IF(AND($D6>$C6,I6>H6),'Tabla general'!$L$4,IF(AND($C6=$D6,H6=I6),'Tabla general'!$L$4,0))) + IF(AND($C6=H6,$D6=I6),'Tabla general'!$L$5,0)) -> 0 | M6: =IF(AND($C6="",$D6=""),0,IF(AND($C6>$D6,K6>L6),'Tabla general'!$L$4,IF(AND($D6>$C6,L6>K6),'Tabla general'!$L$4,IF(AND($C6=$D6,K6=L6),'Tabla general'!$L$4,0))) + IF(AND($C6=K6,$D6=L6),'Tabla general'!$L$5,0)) -> 0 | P6: =IF(AND($C6="",$D6=""),0,IF(AND($C6>$D6,N6>O6),'Tabla general'!$L$4,IF(AND($D6>$C6,O6>N6),'Tabla general'!$L$4,IF(AND($C6=$D6,N6=O6),'Tabla general'!$L$4,0))) + IF(AND($C6=N6,$D6=O6),'Tabla general'!$L$5,0)) -> 0 | S6: =IF(AND($C6="",$D6=""),0,IF(AND($C6>$D6,Q6>R6),'Tabla general'!$L$4,IF(AND($D6>$C6,R6>Q6),'Tabla general'!$L$4,IF(AND($C6=$D6,Q6=R6),'Tabla general'!$L$4,0))) + IF(AND($C6=Q6,$D6=R6),'Tabla general'!$L$5,0)) -> 0 | V6: =IF(AND($C6="",$D6=""),0,IF(AND($C6>$D6,T6>U6),'Tabla general'!$L$4,IF(AND($D6>$C6,U6>T6),'Tabla general'!$L$4,IF(AND($C6=$D6,T6=U6),'Tabla general'!$L$4,0))) + IF(AND($C6=T6,$D6=U6),'Tabla general'!$L$5,0)) -> 0 | Y6: =IF(AND($C6="",$D6=""),0,IF(AND($C6>$D6,W6>X6),'Tabla general'!$L$4,IF(AND($D6>$C6,X6>W6),'Tabla general'!$L$4,IF(AND($C6=$D6,W6=X6),'Tabla general'!$L$4,0))) + IF(AND($C6=W6,$D6=X6),'Tabla general'!$L$5,0)) -> 0 | AB6: =IF(AND($C6="",$D6=""),0,IF(AND($C6>$D6,Z6>AA6),'Tabla general'!$L$4,IF(AND($D6>$C6,AA6>Z6),'Tabla general'!$L$4,IF(AND($C6=$D6,Z6=AA6),'Tabla general'!$L$4,0))) + IF(AND($C6=Z6,$D6=AA6),'Tabla general'!$L$5,0)) -> 0 | AE6: =IF(AND($C6="",$D6=""),0,IF(AND($C6>$D6,AC6>AD6),'Tabla general'!$L$4,IF(AND($D6>$C6,AD6>AC6),'Tabla general'!$L$4,IF(AND($C6=$D6,AC6=AD6),'Tabla general'!$L$4,0))) + IF(AND($C6=AC6,$D6=AD6),'Tabla general'!$L$5,0)) -> 0 | AH6: =IF(AND($C6="",$D6=""),0,IF(AND($C6>$D6,AF6>AG6),'Tabla general'!$L$4,IF(AND($D6>$C6,AG6>AF6),'Tabla general'!$L$4,IF(AND($C6=$D6,AF6=AG6),'Tabla general'!$L$4,0))) + IF(AND($C6=AF6,$D6=AG6),'Tabla general'!$L$5,0)) -> 0 | AK6: =IF(AND($C6="",$D6=""),0,IF(AND($C6>$D6,AI6>AJ6),'Tabla general'!$L$4,IF(AND($D6>$C6,AJ6>AI6),'Tabla general'!$L$4,IF(AND($C6=$D6,AI6=AJ6),'Tabla general'!$L$4,0))) + IF(AND($C6=AI6,$D6=AJ6),'Tabla general'!$L$5,0)) -> 0 | AN6: =IF(AND($C6="",$D6=""),0,IF(AND($C6>$D6,AL6>AM6),'Tabla general'!$L$4,IF(AND($D6>$C6,AM6>AL6),'Tabla general'!$L$4,IF(AND($C6=$D6,AL6=AM6),'Tabla general'!$L$4,0))) + IF(AND($C6=AL6,$D6=AM6),'Tabla general'!$L$5,0)) -> 0 | AQ6: =IF(AND($C6="",$D6=""),0,IF(AND($C6>$D6,AO6>AP6),'Tabla general'!$L$4,IF(AND($D6>$C6,AP6>AO6),'Tabla general'!$L$4,IF(AND($C6=$D6,AO6=AP6),'Tabla general'!$L$4,0))) + IF(AND($C6=AO6,$D6=AP6),'Tabla general'!$L$5,0)) -> 0 | AT6: =IF(AND($C6="",$D6=""),0,IF(AND($C6>$D6,AR6>AS6),'Tabla general'!$L$4,IF(AND($D6>$C6,AS6>AR6),'Tabla general'!$L$4,IF(AND($C6=$D6,AR6=AS6),'Tabla general'!$L$4,0))) + IF(AND($C6=AR6,$D6=AS6),'Tabla general'!$L$5,0)) -> 0 | AW6: =IF(AND($C6="",$D6=""),0,IF(AND($C6>$D6,AU6>AV6),'Tabla general'!$L$4,IF(AND($D6>$C6,AV6>AU6),'Tabla general'!$L$4,IF(AND($C6=$D6,AU6=AV6),'Tabla general'!$L$4,0))) + IF(AND($C6=AU6,$D6=AV6),'Tabla general'!$L$5,0)) -> 0 | AZ6: =IF(AND($C6="",$D6=""),0,IF(AND($C6>$D6,AX6>AY6),'Tabla general'!$L$4,IF(AND($D6>$C6,AY6>AX6),'Tabla general'!$L$4,IF(AND($C6=$D6,AX6=AY6),'Tabla general'!$L$4,0))) + IF(AND($C6=AX6,$D6=AY6),'Tabla general'!$L$5,0)) -> 0
A7: Egipto | B7: Uruguay | G7: =IF(AND($C7="",$D7=""),0,IF(AND($C7>$D7,E7>F7),'Tabla general'!$L$4,IF(AND($D7>$C7,F7>E7),'Tabla general'!$L$4,IF(AND($C7=$D7,E7=F7),'Tabla general'!$L$4,0))) + IF(AND($C7=E7,$D7=F7),'Tabla general'!$L$5,0)) -> 0 | J7: =IF(AND($C7="",$D7=""),0,IF(AND($C7>$D7,H7>I7),'Tabla general'!$L$4,IF(AND($D7>$C7,I7>H7),'Tabla general'!$L$4,IF(AND($C7=$D7,H7=I7),'Tabla general'!$L$4,0))) + IF(AND($C7=H7,$D7=I7),'Tabla general'!$L$5,0)) -> 0 | M7: =IF(AND($C7="",$D7=""),0,IF(AND($C7>$D7,K7>L7),'Tabla general'!$L$4,IF(AND($D7>$C7,L7>K7),'Tabla general'!$L$4,IF(AND($C7=$D7,K7=L7),'Tabla general'!$L$4,0))) + IF(AND($C7=K7,$D7=L7),'Tabla general'!$L$5,0)) -> 0 | P7: =IF(AND($C7="",$D7=""),0,IF(AND($C7>$D7,N7>O7),'Tabla general'!$L$4,IF(AND($D7>$C7,O7>N7),'Tabla general'!$L$4,IF(AND($C7=$D7,N7=O7),'Tabla general'!$L$4,0))) + IF(AND($C7=N7,$D7=O7),'Tabla general'!$L$5,0)) -> 0 | S7: =IF(AND($C7="",$D7=""),0,IF(AND($C7>$D7,Q7>R7),'Tabla general'!$L$4,IF(AND($D7>$C7,R7>Q7),'Tabla general'!$L$4,IF(AND($C7=$D7,Q7=R7),'Tabla general'!$L$4,0))) + IF(AND($C7=Q7,$D7=R7),'Tabla general'!$L$5,0)) -> 0 | V7: =IF(AND($C7="",$D7=""),0,IF(AND($C7>$D7,T7>U7),'Tabla general'!$L$4,IF(AND($D7>$C7,U7>T7),'Tabla general'!$L$4,IF(AND($C7=$D7,T7=U7),'Tabla general'!$L$4,0))) + IF(AND($C7=T7,$D7=U7),'Tabla general'!$L$5,0)) -> 0 | Y7: =IF(AND($C7="",$D7=""),0,IF(AND($C7>$D7,W7>X7),'Tabla general'!$L$4,IF(AND($D7>$C7,X7>W7),'Tabla general'!$L$4,IF(AND($C7=$D7,W7=X7),'Tabla general'!$L$4,0))) + IF(AND($C7=W7,$D7=X7),'Tabla general'!$L$5,0)) -> 0 | AB7: =IF(AND($C7="",$D7=""),0,IF(AND($C7>$D7,Z7>AA7),'Tabla general'!$L$4,IF(AND($D7>$C7,AA7>Z7),'Tabla general'!$L$4,IF(AND($C7=$D7,Z7=AA7),'Tabla general'!$L$4,0))) + IF(AND($C7=Z7,$D7=AA7),'Tabla general'!$L$5,0)) -> 0 | AE7: =IF(AND($C7="",$D7=""),0,IF(AND($C7>$D7,AC7>AD7),'Tabla general'!$L$4,IF(AND($D7>$C7,AD7>AC7),'Tabla general'!$L$4,IF(AND($C7=$D7,AC7=AD7),'Tabla general'!$L$4,0))) + IF(AND($C7=AC7,$D7=AD7),'Tabla general'!$L$5,0)) -> 0 | AH7: =IF(AND($C7="",$D7=""),0,IF(AND($C7>$D7,AF7>AG7),'Tabla general'!$L$4,IF(AND($D7>$C7,AG7>AF7),'Tabla general'!$L$4,IF(AND($C7=$D7,AF7=AG7),'Tabla general'!$L$4,0))) + IF(AND($C7=AF7,$D7=AG7),'Tabla general'!$L$5,0)) -> 0 | AK7: =IF(AND($C7="",$D7=""),0,IF(AND($C7>$D7,AI7>AJ7),'Tabla general'!$L$4,IF(AND($D7>$C7,AJ7>AI7),'Tabla general'!$L$4,IF(AND($C7=$D7,AI7=AJ7),'Tabla general'!$L$4,0))) + IF(AND($C7=AI7,$D7=AJ7),'Tabla general'!$L$5,0)) -> 0 | AN7: =IF(AND($C7="",$D7=""),0,IF(AND($C7>$D7,AL7>AM7),'Tabla general'!$L$4,IF(AND($D7>$C7,AM7>AL7),'Tabla general'!$L$4,IF(AND($C7=$D7,AL7=AM7),'Tabla general'!$L$4,0))) + IF(AND($C7=AL7,$D7=AM7),'Tabla general'!$L$5,0)) -> 0 | AQ7: =IF(AND($C7="",$D7=""),0,IF(AND($C7>$D7,AO7>AP7),'Tabla general'!$L$4,IF(AND($D7>$C7,AP7>AO7),'Tabla general'!$L$4,IF(AND($C7=$D7,AO7=AP7),'Tabla general'!$L$4,0))) + IF(AND($C7=AO7,$D7=AP7),'Tabla general'!$L$5,0)) -> 0 | AT7: =IF(AND($C7="",$D7=""),0,IF(AND($C7>$D7,AR7>AS7),'Tabla general'!$L$4,IF(AND($D7>$C7,AS7>AR7),'Tabla general'!$L$4,IF(AND($C7=$D7,AR7=AS7),'Tabla general'!$L$4,0))) + IF(AND($C7=AR7,$D7=AS7),'Tabla general'!$L$5,0)) -> 0 | AW7: =IF(AND($C7="",$D7=""),0,IF(AND($C7>$D7,AU7>AV7),'Tabla general'!$L$4,IF(AND($D7>$C7,AV7>AU7),'Tabla general'!$L$4,IF(AND($C7=$D7,AU7=AV7),'Tabla general'!$L$4,0))) + IF(AND($C7=AU7,$D7=AV7),'Tabla general'!$L$5,0)) -> 0 | AZ7: =IF(AND($C7="",$D7=""),0,IF(AND($C7>$D7,AX7>AY7),'Tabla general'!$L$4,IF(AND($D7>$C7,AY7>AX7),'Tabla general'!$L$4,IF(AND($C7=$D7,AX7=AY7),'Tabla general'!$L$4,0))) + IF(AND($C7=AX7,$D7=AY7),'Tabla general'!$L$5,0)) -> 0
A8: Marruecos | B8: Rep. De Irán | G8: =IF(AND($C8="",$D8=""),0,IF(AND($C8>$D8,E8>F8),'Tabla general'!$L$4,IF(AND($D8>$C8,F8>E8),'Tabla general'!$L$4,IF(AND($C8=$D8,E8=F8),'Tabla general'!$L$4,0))) + IF(AND($C8=E8,$D8=F8),'Tabla general'!$L$5,0)) -> 0 | J8: =IF(AND($C8="",$D8=""),0,IF(AND($C8>$D8,H8>I8),'Tabla general'!$L$4,IF(AND($D8>$C8,I8>H8),'Tabla general'!$L$4,IF(AND($C8=$D8,H8=I8),'Tabla general'!$L$4,0))) + IF(AND($C8=H8,$D8=I8),'Tabla general'!$L$5,0)) -> 0 | M8: =IF(AND($C8="",$D8=""),0,IF(AND($C8>$D8,K8>L8),'Tabla general'!$L$4,IF(AND($D8>$C8,L8>K8),'Tabla general'!$L$4,IF(AND($C8=$D8,K8=L8),'Tabla general'!$L$4,0))) + IF(AND($C8=K8,$D8=L8),'Tabla general'!$L$5,0)) -> 0 | P8: =IF(AND($C8="",$D8=""),0,IF(AND($C8>$D8,N8>O8),'Tabla general'!$L$4,IF(AND($D8>$C8,O8>N8),'Tabla general'!$L$4,IF(AND($C8=$D8,N8=O8),'Tabla general'!$L$4,0))) + IF(AND($C8=N8,$D8=O8),'Tabla general'!$L$5,0)) -> 0 | S8: =IF(AND($C8="",$D8=""),0,IF(AND($C8>$D8,Q8>R8),'Tabla general'!$L$4,IF(AND($D8>$C8,R8>Q8),'Tabla general'!$L$4,IF(AND($C8=$D8,Q8=R8),'Tabla general'!$L$4,0))) + IF(AND($C8=Q8,$D8=R8),'Tabla general'!$L$5,0)) -> 0 | V8: =IF(AND($C8="",$D8=""),0,IF(AND($C8>$D8,T8>U8),'Tabla general'!$L$4,IF(AND($D8>$C8,U8>T8),'Tabla general'!$L$4,IF(AND($C8=$D8,T8=U8),'Tabla general'!$L$4,0))) + IF(AND($C8=T8,$D8=U8),'Tabla general'!$L$5,0)) -> 0 | Y8: =IF(AND($C8="",$D8=""),0,IF(AND($C8>$D8,W8>X8),'Tabla general'!$L$4,IF(AND($D8>$C8,X8>W8),'Tabla general'!$L$4,IF(AND($C8=$D8,W8=X8),'Tabla general'!$L$4,0))) + IF(AND($C8=W8,$D8=X8),'Tabla general'!$L$5,0)) -> 0 | AB8: =IF(AND($C8="",$D8=""),0,IF(AND($C8>$D8,Z8>AA8),'Tabla general'!$L$4,IF(AND($D8>$C8,AA8>Z8),'Tabla general'!$L$4,IF(AND($C8=$D8,Z8=AA8),'Tabla general'!$L$4,0))) + IF(AND($C8=Z8,$D8=AA8),'Tabla general'!$L$5,0)) -> 0 | AE8: =IF(AND($C8="",$D8=""),0,IF(AND($C8>$D8,AC8>AD8),'Tabla general'!$L$4,IF(AND($D8>$C8,AD8>AC8),'Tabla general'!$L$4,IF(AND($C8=$D8,AC8=AD8),'Tabla general'!$L$4,0))) + IF(AND($C8=AC8,$D8=AD8),'Tabla general'!$L$5,0)) -> 0 | AH8: =IF(AND($C8="",$D8=""),0,IF(AND($C8>$D8,AF8>AG8),'Tabla general'!$L$4,IF(AND($D8>$C8,AG8>AF8),'Tabla general'!$L$4,IF(AND($C8=$D8,AF8=AG8),'Tabla general'!$L$4,0))) + IF(AND($C8=AF8,$D8=AG8),'Tabla general'!$L$5,0)) -> 0 | AK8: =IF(AND($C8="",$D8=""),0,IF(AND($C8>$D8,AI8>AJ8),'Tabla general'!$L$4,IF(AND($D8>$C8,AJ8>AI8),'Tabla general'!$L$4,IF(AND($C8=$D8,AI8=AJ8),'Tabla general'!$L$4,0))) + IF(AND($C8=AI8,$D8=AJ8),'Tabla general'!$L$5,0)) -> 0 | AN8: =IF(AND($C8="",$D8=""),0,IF(AND($C8>$D8,AL8>AM8),'Tabla general'!$L$4,IF(AND($D8>$C8,AM8>AL8),'Tabla general'!$L$4,IF(AND($C8=$D8,AL8=AM8),'Tabla general'!$L$4,0))) + IF(AND($C8=AL8,$D8=AM8),'Tabla general'!$L$5,0)) -> 0 | AQ8: =IF(AND($C8="",$D8=""),0,IF(AND($C8>$D8,AO8>AP8),'Tabla general'!$L$4,IF(AND($D8>$C8,AP8>AO8),'Tabla general'!$L$4,IF(AND($C8=$D8,AO8=AP8),'Tabla general'!$L$4,0))) + IF(AND($C8=AO8,$D8=AP8),'Tabla general'!$L$5,0)) -> 0 | AT8: =IF(AND($C8="",$D8=""),0,IF(AND($C8>$D8,AR8>AS8),'Tabla general'!$L$4,IF(AND($D8>$C8,AS8>AR8),'Tabla general'!$L$4,IF(AND($C8=$D8,AR8=AS8),'Tabla general'!$L$4,0))) + IF(AND($C8=AR8,$D8=AS8),'Tabla general'!$L$5,0)) -> 0 | AW8: =IF(AND($C8="",$D8=""),0,IF(AND($C8>$D8,AU8>AV8),'Tabla general'!$L$4,IF(AND($D8>$C8,AV8>AU8),'Tabla general'!$L$4,IF(AND($C8=$D8,AU8=AV8),'Tabla general'!$L$4,0))) + IF(AND($C8=AU8,$D8=AV8),'Tabla general'!$L$5,0)) -> 0 | AZ8: =IF(AND($C8="",$D8=""),0,IF(AND($C8>$D8,AX8>AY8),'Tabla general'!$L$4,IF(AND($D8>$C8,AY8>AX8),'Tabla general'!$L$4,IF(AND($C8=$D8,AX8=AY8),'Tabla general'!$L$4,0))) + IF(AND($C8=AX8,$D8=AY8),'Tabla general'!$L$5,0)) -> 0
A9: Portugal | B9: España | G9: =IF(AND($C9="",$D9=""),0,IF(AND($C9>$D9,E9>F9),'Tabla general'!$L$4,IF(AND($D9>$C9,F9>E9),'Tabla general'!$L$4,IF(AND($C9=$D9,E9=F9),'Tabla general'!$L$4,0))) + IF(AND($C9=E9,$D9=F9),'Tabla general'!$L$5,0)) -> 0 | J9: =IF(AND($C9="",$D9=""),0,IF(AND($C9>$D9,H9>I9),'Tabla general'!$L$4,IF(AND($D9>$C9,I9>H9),'Tabla general'!$L$4,IF(AND($C9=$D9,H9=I9),'Tabla general'!$L$4,0))) + IF(AND($C9=H9,$D9=I9),'Tabla general'!$L$5,0)) -> 0 | M9: =IF(AND($C9="",$D9=""),0,IF(AND($C9>$D9,K9>L9),'Tabla general'!$L$4,IF(AND($D9>$C9,L9>K9),'Tabla general'!$L$4,IF(AND($C9=$D9,K9=L9),'Tabla general'!$L$4,0))) + IF(AND($C9=K9,$D9=L9),'Tabla general'!$L$5,0)) -> 0 | P9: =IF(AND($C9="",$D9=""),0,IF(AND($C9>$D9,N9>O9),'Tabla general'!$L$4,IF(AND($D9>$C9,O9>N9),'Tabla general'!$L$4,IF(AND($C9=$D9,N9=O9),'Tabla general'!$L$4,0))) + IF(AND($C9=N9,$D9=O9),'Tabla general'!$L$5,0)) -> 0 | S9: =IF(AND($C9="",$D9=""),0,IF(AND($C9>$D9,Q9>R9),'Tabla general'!$L$4,IF(AND($D9>$C9,R9>Q9),'Tabla general'!$L$4,IF(AND($C9=$D9,Q9=R9),'Tabla general'!$L$4,0))) + IF(AND($C9=Q9,$D9=R9),'Tabla general'!$L$5,0)) -> 0 | V9: =IF(AND($C9="",$D9=""),0,IF(AND($C9>$D9,T9>U9),'Tabla general'!$L$4,IF(AND($D9>$C9,U9>T9),'Tabla general'!$L$4,IF(AND($C9=$D9,T9=U9),'Tabla general'!$L$4,0))) + IF(AND($C9=T9,$D9=U9),'Tabla general'!$L$5,0)) -> 0 | Y9: =IF(AND($C9="",$D9=""),0,IF(AND($C9>$D9,W9>X9),'Tabla general'!$L$4,IF(AND($D9>$C9,X9>W9),'Tabla general'!$L$4,IF(AND($C9=$D9,W9=X9),'Tabla general'!$L$4,0))) + IF(AND($C9=W9,$D9=X9),'Tabla general'!$L$5,0)) -> 0 | AB9: =IF(AND($C9="",$D9=""),0,IF(AND($C9>$D9,Z9>AA9),'Tabla general'!$L$4,IF(AND($D9>$C9,AA9>Z9),'Tabla general'!$L$4,IF(AND($C9=$D9,Z9=AA9),'Tabla general'!$L$4,0))) + IF(AND($C9=Z9,$D9=AA9),'Tabla general'!$L$5,0)) -> 0 | AE9: =IF(AND($C9="",$D9=""),0,IF(AND($C9>$D9,AC9>AD9),'Tabla general'!$L$4,IF(AND($D9>$C9,AD9>AC9),'Tabla general'!$L$4,IF(AND($C9=$D9,AC9=AD9),'Tabla general'!$L$4,0))) + IF(AND($C9=AC9,$D9=AD9),'Tabla general'!$L$5,0)) -> 0 | AH9: =IF(AND($C9="",$D9=""),0,IF(AND($C9>$D9,AF9>AG9),'Tabla general'!$L$4,IF(AND($D9>$C9,AG9>AF9),'Tabla general'!$L$4,IF(AND($C9=$D9,AF9=AG9),'Tabla general'!$L$4,0))) + IF(AND($C9=AF9,$D9=AG9),'Tabla general'!$L$5,0)) -> 0 | AK9: =IF(AND($C9="",$D9=""),0,IF(AND($C9>$D9,AI9>AJ9),'Tabla general'!$L$4,IF(AND($D9>$C9,AJ9>AI9),'Tabla general'!$L$4,IF(AND($C9=$D9,AI9=AJ9),'Tabla general'!$L$4,0))) + IF(AND($C9=AI9,$D9=AJ9),'Tabla general'!$L$5,0)) -> 0 | AN9: =IF(AND($C9="",$D9=""),0,IF(AND($C9>$D9,AL9>AM9),'Tabla general'!$L$4,IF(AND($D9>$C9,AM9>AL9),'Tabla general'!$L$4,IF(AND($C9=$D9,AL9=AM9),'Tabla general'!$L$4,0))) + IF(AND($C9=AL9,$D9=AM9),'Tabla general'!$L$5,0)) -> 0 | AQ9: =IF(AND($C9="",$D9=""),0,IF(AND($C9>$D9,AO9>AP9),'Tabla general'!$L$4,IF(AND($D9>$C9,AP9>AO9),'Tabla general'!$L$4,IF(AND($C9=$D9,AO9=AP9),'Tabla general'!$L$4,0))) + IF(AND($C9=AO9,$D9=AP9),'Tabla general'!$L$5,0)) -> 0 | AT9: =IF(AND($C9="",$D9=""),0,IF(AND($C9>$D9,AR9>AS9),'Tabla general'!$L$4,IF(AND($D9>$C9,AS9>AR9),'Tabla general'!$L$4,IF(AND($C9=$D9,AR9=AS9),'Tabla general'!$L$4,0))) + IF(AND($C9=AR9,$D9=AS9),'Tabla general'!$L$5,0)) -> 0 | AW9: =IF(AND($C9="",$D9=""),0,IF(AND($C9>$D9,AU9>AV9),'Tabla general'!$L$4,IF(AND($D9>$C9,AV9>AU9),'Tabla general'!$L$4,IF(AND($C9=$D9,AU9=AV9),'Tabla general'!$L$4,0))) + IF(AND($C9=AU9,$D9=AV9),'Tabla general'!$L$5,0)) -> 0 | AZ9: =IF(AND($C9="",$D9=""),0,IF(AND($C9>$D9,AX9>AY9),'Tabla general'!$L$4,IF(AND($D9>$C9,AY9>AX9),'Tabla general'!$L$4,IF(AND($C9=$D9,AX9=AY9),'Tabla general'!$L$4,0))) + IF(AND($C9=AX9,$D9=AY9),'Tabla general'!$L$5,0)) -> 0
A10: Francia | B10: Australia | G10: =IF(AND($C10="",$D10=""),0,IF(AND($C10>$D10,E10>F10),'Tabla general'!$L$4,IF(AND($D10>$C10,F10>E10),'Tabla general'!$L$4,IF(AND($C10=$D10,E10=F10),'Tabla general'!$L$4,0))) + IF(AND($C10=E10,$D10=F10),'Tabla general'!$L$5,0)) -> 0 | J10: =IF(AND($C10="",$D10=""),0,IF(AND($C10>$D10,H10>I10),'Tabla general'!$L$4,IF(AND($D10>$C10,I10>H10),'Tabla general'!$L$4,IF(AND($C10=$D10,H10=I10),'Tabla general'!$L$4,0))) + IF(AND($C10=H10,$D10=I10),'Tabla general'!$L$5,0)) -> 0 | M10: =IF(AND($C10="",$D10=""),0,IF(AND($C10>$D10,K10>L10),'Tabla general'!$L$4,IF(AND($D10>$C10,L10>K10),'Tabla general'!$L$4,IF(AND($C10=$D10,K10=L10),'Tabla general'!$L$4,0))) + IF(AND($C10=K10,$D10=L10),'Tabla general'!$L$5,0)) -> 0 | P10: =IF(AND($C10="",$D10=""),0,IF(AND($C10>$D10,N10>O10),'Tabla general'!$L$4,IF(AND($D10>$C10,O10>N10),'Tabla general'!$L$4,IF(AND($C10=$D10,N10=O10),'Tabla general'!$L$4,0))) + IF(AND($C10=N10,$D10=O10),'Tabla general'!$L$5,0)) -> 0 | S10: =IF(AND($C10="",$D10=""),0,IF(AND($C10>$D10,Q10>R10),'Tabla general'!$L$4,IF(AND($D10>$C10,R10>Q10),'Tabla general'!$L$4,IF(AND($C10=$D10,Q10=R10),'Tabla general'!$L$4,0))) + IF(AND($C10=Q10,$D10=R10),'Tabla general'!$L$5,0)) -> 0 | V10: =IF(AND($C10="",$D10=""),0,IF(AND($C10>$D10,T10>U10),'Tabla general'!$L$4,IF(AND($D10>$C10,U10>T10),'Tabla general'!$L$4,IF(AND($C10=$D10,T10=U10),'Tabla general'!$L$4,0))) + IF(AND($C10=T10,$D10=U10),'Tabla general'!$L$5,0)) -> 0 | Y10: =IF(AND($C10="",$D10=""),0,IF(AND($C10>$D10,W10>X10),'Tabla general'!$L$4,IF(AND($D10>$C10,X10>W10),'Tabla general'!$L$4,IF(AND($C10=$D10,W10=X10),'Tabla general'!$L$4,0))) + IF(AND($C10=W10,$D10=X10),'Tabla general'!$L$5,0)) -> 0 | AB10: =IF(AND($C10="",$D10=""),0,IF(AND($C10>$D10,Z10>AA10),'Tabla general'!$L$4,IF(AND($D10>$C10,AA10>Z10),'Tabla general'!$L$4,IF(AND($C10=$D10,Z10=AA10),'Tabla general'!$L$4,0))) + IF(AND($C10=Z10,$D10=AA10),'Tabla general'!$L$5,0)) -> 0 | AE10: =IF(AND($C10="",$D10=""),0,IF(AND($C10>$D10,AC10>AD10),'Tabla general'!$L$4,IF(AND($D10>$C10,AD10>AC10),'Tabla general'!$L$4,IF(AND($C10=$D10,AC10=AD10),'Tabla general'!$L$4,0))) + IF(AND($C10=AC10,$D10=AD10),'Tabla general'!$L$5,0)) -> 0 | AH10: =IF(AND($C10="",$D10=""),0,IF(AND($C10>$D10,AF10>AG10),'Tabla general'!$L$4,IF(AND($D10>$C10,AG10>AF10),'Tabla general'!$L$4,IF(AND($C10=$D10,AF10=AG10),'Tabla general'!$L$4,0))) + IF(AND($C10=AF10,$D10=AG10),'Tabla general'!$L$5,0)) -> 0 | AK10: =IF(AND($C10="",$D10=""),0,IF(AND($C10>$D10,AI10>AJ10),'Tabla general'!$L$4,IF(AND($D10>$C10,AJ10>AI10),'Tabla general'!$L$4,IF(AND($C10=$D10,AI10=AJ10),'Tabla general'!$L$4,0))) + IF(AND($C10=AI10,$D10=AJ10),'Tabla general'!$L$5,0)) -> 0 | AN10: =IF(AND($C10="",$D10=""),0,IF(AND($C10>$D10,AL10>AM10),'Tabla general'!$L$4,IF(AND($D10>$C10,AM10>AL10),'Tabla general'!$L$4,IF(AND($C10=$D10,AL10=AM10),'Tabla general'!$L$4,0))) + IF(AND($C10=AL10,$D10=AM10),'Tabla general'!$L$5,0)) -> 0 | AQ10: =IF(AND($C10="",$D10=""),0,IF(AND($C10>$D10,AO10>AP10),'Tabla general'!$L$4,IF(AND($D10>$C10,AP10>AO10),'Tabla general'!$L$4,IF(AND($C10=$D10,AO10=AP10),'Tabla general'!$L$4,0))) + IF(AND($C10=AO10,$D10=AP10),'Tabla general'!$L$5,0)) -> 0 | AT10: =IF(AND($C10="",$D10=""),0,IF(AND($C10>$D10,AR10>AS10),'Tabla general'!$L$4,IF(AND($D10>$C10,AS10>AR10),'Tabla general'!$L$4,IF(AND($C10=$D10,AR10=AS10),'Tabla general'!$L$4,0))) + IF(AND($C10=AR10,$D10=AS10),'Tabla general'!$L$5,0)) -> 0 | AW10: =IF(AND($C10="",$D10=""),0,IF(AND($C10>$D10,AU10>AV10),'Tabla general'!$L$4,IF(AND($D10>$C10,AV10>AU10),'Tabla general'!$L$4,IF(AND($C10=$D10,AU10=AV10),'Tabla general'!$L$4,0))) + IF(AND($C10=AU10,$D10=AV10),'Tabla general'!$L$5,0)) -> 0 | AZ10: =IF(AND($C10="",$D10=""),0,IF(AND($C10>$D10,AX10>AY10),'Tabla general'!$L$4,IF(AND($D10>$C10,AY10>AX10),'Tabla general'!$L$4,IF(AND($C10=$D10,AX10=AY10),'Tabla general'!$L$4,0))) + IF(AND($C10=AX10,$D10=AY10),'Tabla general'!$L$5,0)) -> 0
A11: Argentina | B11: Islandia | G11: =IF(AND($C11="",$D11=""),0,IF(AND($C11>$D11,E11>F11),'Tabla general'!$L$4,IF(AND($D11>$C11,F11>E11),'Tabla general'!$L$4,IF(AND($C11=$D11,E11=F11),'Tabla general'!$L$4,0))) + IF(AND($C11=E11,$D11=F11),'Tabla general'!$L$5,0)) -> 0 | J11: =IF(AND($C11="",$D11=""),0,IF(AND($C11>$D11,H11>I11),'Tabla general'!$L$4,IF(AND($D11>$C11,I11>H11),'Tabla general'!$L$4,IF(AND($C11=$D11,H11=I11),'Tabla general'!$L$4,0))) + IF(AND($C11=H11,$D11=I11),'Tabla general'!$L$5,0)) -> 0 | M11: =IF(AND($C11="",$D11=""),0,IF(AND($C11>$D11,K11>L11),'Tabla general'!$L$4,IF(AND($D11>$C11,L11>K11),'Tabla general'!$L$4,IF(AND($C11=$D11,K11=L11),'Tabla general'!$L$4,0))) + IF(AND($C11=K11,$D11=L11),'Tabla general'!$L$5,0)) -> 0 | P11: =IF(AND($C11="",$D11=""),0,IF(AND($C11>$D11,N11>O11),'Tabla general'!$L$4,IF(AND($D11>$C11,O11>N11),'Tabla general'!$L$4,IF(AND($C11=$D11,N11=O11),'Tabla general'!$L$4,0))) + IF(AND($C11=N11,$D11=O11),'Tabla general'!$L$5,0)) -> 0 | S11: =IF(AND($C11="",$D11=""),0,IF(AND($C11>$D11,Q11>R11),'Tabla general'!$L$4,IF(AND($D11>$C11,R11>Q11),'Tabla general'!$L$4,IF(AND($C11=$D11,Q11=R11),'Tabla general'!$L$4,0))) + IF(AND($C11=Q11,$D11=R11),'Tabla general'!$L$5,0)) -> 0 | V11: =IF(AND($C11="",$D11=""),0,IF(AND($C11>$D11,T11>U11),'Tabla general'!$L$4,IF(AND($D11>$C11,U11>T11),'Tabla general'!$L$4,IF(AND($C11=$D11,T11=U11),'Tabla general'!$L$4,0))) + IF(AND($C11=T11,$D11=U11),'Tabla general'!$L$5,0)) -> 0 | Y11: =IF(AND($C11="",$D11=""),0,IF(AND($C11>$D11,W11>X11),'Tabla general'!$L$4,IF(AND($D11>$C11,X11>W11),'Tabla general'!$L$4,IF(AND($C11=$D11,W11=X11),'Tabla general'!$L$4,0))) + IF(AND($C11=W11,$D11=X11),'Tabla general'!$L$5,0)) -> 0 | AB11: =IF(AND($C11="",$D11=""),0,IF(AND($C11>$D11,Z11>AA11),'Tabla general'!$L$4,IF(AND($D11>$C11,AA11>Z11),'Tabla general'!$L$4,IF(AND($C11=$D11,Z11=AA11),'Tabla general'!$L$4,0))) + IF(AND($C11=Z11,$D11=AA11),'Tabla general'!$L$5,0)) -> 0 | AE11: =IF(AND($C11="",$D11=""),0,IF(AND($C11>$D11,AC11>AD11),'Tabla general'!$L$4,IF(AND($D11>$C11,AD11>AC11),'Tabla general'!$L$4,IF(AND($C11=$D11,AC11=AD11),'Tabla general'!$L$4,0))) + IF(AND($C11=AC11,$D11=AD11),'Tabla general'!$L$5,0)) -> 0 | AH11: =IF(AND($C11="",$D11=""),0,IF(AND($C11>$D11,AF11>AG11),'Tabla general'!$L$4,IF(AND($D11>$C11,AG11>AF11),'Tabla general'!$L$4,IF(AND($C11=$D11,AF11=AG11),'Tabla general'!$L$4,0))) + IF(AND($C11=AF11,$D11=AG11),'Tabla general'!$L$5,0)) -> 0 | AK11: =IF(AND($C11="",$D11=""),0,IF(AND($C11>$D11,AI11>AJ11),'Tabla general'!$L$4,IF(AND($D11>$C11,AJ11>AI11),'Tabla general'!$L$4,IF(AND($C11=$D11,AI11=AJ11),'Tabla general'!$L$4,0))) + IF(AND($C11=AI11,$D11=AJ11),'Tabla general'!$L$5,0)) -> 0 | AN11: =IF(AND($C11="",$D11=""),0,IF(AND($C11>$D11,AL11>AM11),'Tabla general'!$L$4,IF(AND($D11>$C11,AM11>AL11),'Tabla general'!$L$4,IF(AND($C11=$D11,AL11=AM11),'Tabla general'!$L$4,0))) + IF(AND($C11=AL11,$D11=AM11),'Tabla general'!$L$5,0)) -> 0 | AQ11: =IF(AND($C11="",$D11=""),0,IF(AND($C11>$D11,AO11>AP11),'Tabla general'!$L$4,IF(AND($D11>$C11,AP11>AO11),'Tabla general'!$L$4,IF(AND($C11=$D11,AO11=AP11),'Tabla general'!$L$4,0))) + IF(AND($C11=AO11,$D11=AP11),'Tabla general'!$L$5,0)) -> 0 | AT11: =IF(AND($C11="",$D11=""),0,IF(AND($C11>$D11,AR11>AS11),'Tabla general'!$L$4,IF(AND($D11>$C11,AS11>AR11),'Tabla general'!$L$4,IF(AND($C11=$D11,AR11=AS11),'Tabla general'!$L$4,0))) + IF(AND($C11=AR11,$D11=AS11),'Tabla general'!$L$5,0)) -> 0 | AW11: =IF(AND($C11="",$D11=""),0,IF(AND($C11>$D11,AU11>AV11),'Tabla general'!$L$4,IF(AND($D11>$C11,AV11>AU11),'Tabla general'!$L$4,IF(AND($C11=$D11,AU11=AV11),'Tabla general'!$L$4,0))) + IF(AND($C11=AU11,$D11=AV11),'Tabla general'!$L$5,0)) -> 0 | AZ11: =IF(AND($C11="",$D11=""),0,IF(AND($C11>$D11,AX11>AY11),'Tabla general'!$L$4,IF(AND($D11>$C11,AY11>AX11),'Tabla general'!$L$4,IF(AND($C11=$D11,AX11=AY11),'Tabla general'!$L$4,0))) + IF(AND($C11=AX11,$D11=AY11),'Tabla general'!$L$5,0)) -> 0
A12: Perú | B12: Dinamarca | G12: =IF(AND($C12="",$D12=""),0,IF(AND($C12>$D12,E12>F12),'Tabla general'!$L$4,IF(AND($D12>$C12,F12>E12),'Tabla general'!$L$4,IF(AND($C12=$D12,E12=F12),'Tabla general'!$L$4,0))) + IF(AND($C12=E12,$D12=F12),'Tabla general'!$L$5,0)) -> 0 | J12: =IF(AND($C12="",$D12=""),0,IF(AND($C12>$D12,H12>I12),'Tabla general'!$L$4,IF(AND($D12>$C12,I12>H12),'Tabla general'!$L$4,IF(AND($C12=$D12,H12=I12),'Tabla general'!$L$4,0))) + IF(AND($C12=H12,$D12=I12),'Tabla general'!$L$5,0)) -> 0 | M12: =IF(AND($C12="",$D12=""),0,IF(AND($C12>$D12,K12>L12),'Tabla general'!$L$4,IF(AND($D12>$C12,L12>K12),'Tabla general'!$L$4,IF(AND($C12=$D12,K12=L12),'Tabla general'!$L$4,0))) + IF(AND($C12=K12,$D12=L12),'Tabla general'!$L$5,0)) -> 0 | P12: =IF(AND($C12="",$D12=""),0,IF(AND($C12>$D12,N12>O12),'Tabla general'!$L$4,IF(AND($D12>$C12,O12>N12),'Tabla general'!$L$4,IF(AND($C12=$D12,N12=O12),'Tabla general'!$L$4,0))) + IF(AND($C12=N12,$D12=O12),'Tabla general'!$L$5,0)) -> 0 | S12: =IF(AND($C12="",$D12=""),0,IF(AND($C12>$D12,Q12>R12),'Tabla general'!$L$4,IF(AND($D12>$C12,R12>Q12),'Tabla general'!$L$4,IF(AND($C12=$D12,Q12=R12),'Tabla general'!$L$4,0))) + IF(AND($C12=Q12,$D12=R12),'Tabla general'!$L$5,0)) -> 0 | V12: =IF(AND($C12="",$D12=""),0,IF(AND($C12>$D12,T12>U12),'Tabla general'!$L$4,IF(AND($D12>$C12,U12>T12),'Tabla general'!$L$4,IF(AND($C12=$D12,T12=U12),'Tabla general'!$L$4,0))) + IF(AND($C12=T12,$D12=U12),'Tabla general'!$L$5,0)) -> 0 | Y12: =IF(AND($C12="",$D12=""),0,IF(AND($C12>$D12,W12>X12),'Tabla general'!$L$4,IF(AND($D12>$C12,X12>W12),'Tabla general'!$L$4,IF(AND($C12=$D12,W12=X12),'Tabla general'!$L$4,0))) + IF(AND($C12=W12,$D12=X12),'Tabla general'!$L$5,0)) -> 0 | AB12: =IF(AND($C12="",$D12=""),0,IF(AND($C12>$D12,Z12>AA12),'Tabla general'!$L$4,IF(AND($D12>$C12,AA12>Z12),'Tabla general'!$L$4,IF(AND($C12=$D12,Z12=AA12),'Tabla general'!$L$4,0))) + IF(AND($C12=Z12,$D12=AA12),'Tabla general'!$L$5,0)) -> 0 | AE12: =IF(AND($C12="",$D12=""),0,IF(AND($C12>$D12,AC12>AD12),'Tabla general'!$L$4,IF(AND($D12>$C12,AD12>AC12),'Tabla general'!$L$4,IF(AND($C12=$D12,AC12=AD12),'Tabla general'!$L$4,0))) + IF(AND($C12=AC12,$D12=AD12),'Tabla general'!$L$5,0)) -> 0 | AH12: =IF(AND($C12="",$D12=""),0,IF(AND($C12>$D12,AF12>AG12),'Tabla general'!$L$4,IF(AND($D12>$C12,AG12>AF12),'Tabla general'!$L$4,IF(AND($C12=$D12,AF12=AG12),'Tabla general'!$L$4,0))) + IF(AND($C12=AF12,$D12=AG12),'Tabla general'!$L$5,0)) -> 0 | AK12: =IF(AND($C12="",$D12=""),0,IF(AND($C12>$D12,AI12>AJ12),'Tabla general'!$L$4,IF(AND($D12>$C12,AJ12>AI12),'Tabla general'!$L$4,IF(AND($C12=$D12,AI12=AJ12),'Tabla general'!$L$4,0))) + IF(AND($C12=AI12,$D12=AJ12),'Tabla general'!$L$5,0)) -> 0 | AN12: =IF(AND($C12="",$D12=""),0,IF(AND($C12>$D12,AL12>AM12),'Tabla general'!$L$4,IF(AND($D12>$C12,AM12>AL12),'Tabla general'!$L$4,IF(AND($C12=$D12,AL12=AM12),'Tabla general'!$L$4,0))) + IF(AND($C12=AL12,$D12=AM12),'Tabla general'!$L$5,0)) -> 0 | AQ12: =IF(AND($C12="",$D12=""),0,IF(AND($C12>$D12,AO12>AP12),'Tabla general'!$L$4,IF(AND($D12>$C12,AP12>AO12),'Tabla general'!$L$4,IF(AND($C12=$D12,AO12=AP12),'Tabla general'!$L$4,0))) + IF(AND($C12=AO12,$D12=AP12),'Tabla general'!$L$5,0)) -> 0 | AT12: =IF(AND($C12="",$D12=""),0,IF(AND($C12>$D12,AR12>AS12),'Tabla general'!$L$4,IF(AND($D12>$C12,AS12>AR12),'Tabla general'!$L$4,IF(AND($C12=$D12,AR12=AS12),'Tabla general'!$L$4,0))) + IF(AND($C12=AR12,$D12=AS12),'Tabla general'!$L$5,0)) -> 0 | AW12: =IF(AND($C12="",$D12=""),0,IF(AND($C12>$D12,AU12>AV12),'Tabla general'!$L$4,IF(AND($D12>$C12,AV12>AU12),'Tabla general'!$L$4,IF(AND($C12=$D12,AU12=AV12),'Tabla general'!$L$4,0))) + IF(AND($C12=AU12,$D12=AV12),'Tabla general'!$L$5,0)) -> 0 | AZ12: =IF(AND($C12="",$D12=""),0,IF(AND($C12>$D12,AX12>AY12),'Tabla general'!$L$4,IF(AND($D12>$C12,AY12>AX12),'Tabla general'!$L$4,IF(AND($C12=$D12,AX12=AY12),'Tabla general'!$L$4,0))) + IF(AND($C12=AX12,$D12=AY12),'Tabla general'!$L$5,0)) -> 0
A13: Croacia | B13: Nigeria | G13: =IF(AND($C13="",$D13=""),0,IF(AND($C13>$D13,E13>F13),'Tabla general'!$L$4,IF(AND($D13>$C13,F13>E13),'Tabla general'!$L$4,IF(AND($C13=$D13,E13=F13),'Tabla general'!$L$4,0))) + IF(AND($C13=E13,$D13=F13),'Tabla general'!$L$5,0)) -> 0 | J13: =IF(AND($C13="",$D13=""),0,IF(AND($C13>$D13,H13>I13),'Tabla general'!$L$4,IF(AND($D13>$C13,I13>H13),'Tabla general'!$L$4,IF(AND($C13=$D13,H13=I13),'Tabla general'!$L$4,0))) + IF(AND($C13=H13,$D13=I13),'Tabla general'!$L$5,0)) -> 0 | M13: =IF(AND($C13="",$D13=""),0,IF(AND($C13>$D13,K13>L13),'Tabla general'!$L$4,IF(AND($D13>$C13,L13>K13),'Tabla general'!$L$4,IF(AND($C13=$D13,K13=L13),'Tabla general'!$L$4,0))) + IF(AND($C13=K13,$D13=L13),'Tabla general'!$L$5,0)) -> 0 | P13: =IF(AND($C13="",$D13=""),0,IF(AND($C13>$D13,N13>O13),'Tabla general'!$L$4,IF(AND($D13>$C13,O13>N13),'Tabla general'!$L$4,IF(AND($C13=$D13,N13=O13),'Tabla general'!$L$4,0))) + IF(AND($C13=N13,$D13=O13),'Tabla general'!$L$5,0)) -> 0 | S13: =IF(AND($C13="",$D13=""),0,IF(AND($C13>$D13,Q13>R13),'Tabla general'!$L$4,IF(AND($D13>$C13,R13>Q13),'Tabla general'!$L$4,IF(AND($C13=$D13,Q13=R13),'Tabla general'!$L$4,0))) + IF(AND($C13=Q13,$D13=R13),'Tabla general'!$L$5,0)) -> 0 | V13: =IF(AND($C13="",$D13=""),0,IF(AND($C13>$D13,T13>U13),'Tabla general'!$L$4,IF(AND($D13>$C13,U13>T13),'Tabla general'!$L$4,IF(AND($C13=$D13,T13=U13),'Tabla general'!$L$4,0))) + IF(AND($C13=T13,$D13=U13),'Tabla general'!$L$5,0)) -> 0 | Y13: =IF(AND($C13="",$D13=""),0,IF(AND($C13>$D13,W13>X13),'Tabla general'!$L$4,IF(AND($D13>$C13,X13>W13),'Tabla general'!$L$4,IF(AND($C13=$D13,W13=X13),'Tabla general'!$L$4,0))) + IF(AND($C13=W13,$D13=X13),'Tabla general'!$L$5,0)) -> 0 | AB13: =IF(AND($C13="",$D13=""),0,IF(AND($C13>$D13,Z13>AA13),'Tabla general'!$L$4,IF(AND($D13>$C13,AA13>Z13),'Tabla general'!$L$4,IF(AND($C13=$D13,Z13=AA13),'Tabla general'!$L$4,0))) + IF(AND($C13=Z13,$D13=AA13),'Tabla general'!$L$5,0)) -> 0 | AE13: =IF(AND($C13="",$D13=""),0,IF(AND($C13>$D13,AC13>AD13),'Tabla general'!$L$4,IF(AND($D13>$C13,AD13>AC13),'Tabla general'!$L$4,IF(AND($C13=$D13,AC13=AD13),'Tabla general'!$L$4,0))) + IF(AND($C13=AC13,$D13=AD13),'Tabla general'!$L$5,0)) -> 0 | AH13: =IF(AND($C13="",$D13=""),0,IF(AND($C13>$D13,AF13>AG13),'Tabla general'!$L$4,IF(AND($D13>$C13,AG13>AF13),'Tabla general'!$L$4,IF(AND($C13=$D13,AF13=AG13),'Tabla general'!$L$4,0))) + IF(AND($C13=AF13,$D13=AG13),'Tabla general'!$L$5,0)) -> 0 | AK13: =IF(AND($C13="",$D13=""),0,IF(AND($C13>$D13,AI13>AJ13),'Tabla general'!$L$4,IF(AND($D13>$C13,AJ13>AI13),'Tabla general'!$L$4,IF(AND($C13=$D13,AI13=AJ13),'Tabla general'!$L$4,0))) + IF(AND($C13=AI13,$D13=AJ13),'Tabla general'!$L$5,0)) -> 0 | AN13: =IF(AND($C13="",$D13=""),0,IF(AND($C13>$D13,AL13>AM13),'Tabla general'!$L$4,IF(AND($D13>$C13,AM13>AL13),'Tabla general'!$L$4,IF(AND($C13=$D13,AL13=AM13),'Tabla general'!$L$4,0))) + IF(AND($C13=AL13,$D13=AM13),'Tabla general'!$L$5,0)) -> 0 | AQ13: =IF(AND($C13="",$D13=""),0,IF(AND($C13>$D13,AO13>AP13),'Tabla general'!$L$4,IF(AND($D13>$C13,AP13>AO13),'Tabla general'!$L$4,IF(AND($C13=$D13,AO13=AP13),'Tabla general'!$L$4,0))) + IF(AND($C13=AO13,$D13=AP13),'Tabla general'!$L$5,0)) -> 0 | AT13: =IF(AND($C13="",$D13=""),0,IF(AND($C13>$D13,AR13>AS13),'Tabla general'!$L$4,IF(AND($D13>$C13,AS13>AR13),'Tabla general'!$L$4,IF(AND($C13=$D13,AR13=AS13),'Tabla general'!$L$4,0))) + IF(AND($C13=AR13,$D13=AS13),'Tabla general'!$L$5,0)) -> 0 | AW13: =IF(AND($C13="",$D13=""),0,IF(AND($C13>$D13,AU13>AV13),'Tabla general'!$L$4,IF(AND($D13>$C13,AV13>AU13),'Tabla general'!$L$4,IF(AND($C13=$D13,AU13=AV13),'Tabla general'!$L$4,0))) + IF(AND($C13=AU13,$D13=AV13),'Tabla general'!$L$5,0)) -> 0 | AZ13: =IF(AND($C13="",$D13=""),0,IF(AND($C13>$D13,AX13>AY13),'Tabla general'!$L$4,IF(AND($D13>$C13,AY13>AX13),'Tabla general'!$L$4,IF(AND($C13=$D13,AX13=AY13),'Tabla general'!$L$4,0))) + IF(AND($C13=AX13,$D13=AY13),'Tabla general'!$L$5,0)) -> 0
A14: Costa Rica | B14: Serbia | G14: =IF(AND($C14="",$D14=""),0,IF(AND($C14>$D14,E14>F14),'Tabla general'!$L$4,IF(AND($D14>$C14,F14>E14),'Tabla general'!$L$4,IF(AND($C14=$D14,E14=F14),'Tabla general'!$L$4,0))) + IF(AND($C14=E14,$D14=F14),'Tabla general'!$L$5,0)) -> 0 | J14: =IF(AND($C14="",$D14=""),0,IF(AND($C14>$D14,H14>I14),'Tabla general'!$L$4,IF(AND($D14>$C14,I14>H14),'Tabla general'!$L$4,IF(AND($C14=$D14,H14=I14),'Tabla general'!$L$4,0))) + IF(AND($C14=H14,$D14=I14),'Tabla general'!$L$5,0)) -> 0 | M14: =IF(AND($C14="",$D14=""),0,IF(AND($C14>$D14,K14>L14),'Tabla general'!$L$4,IF(AND($D14>$C14,L14>K14),'Tabla general'!$L$4,IF(AND($C14=$D14,K14=L14),'Tabla general'!$L$4,0))) + IF(AND($C14=K14,$D14=L14),'Tabla general'!$L$5,0)) -> 0 | P14: =IF(AND($C14="",$D14=""),0,IF(AND($C14>$D14,N14>O14),'Tabla general'!$L$4,IF(AND($D14>$C14,O14>N14),'Tabla general'!$L$4,IF(AND($C14=$D14,N14=O14),'Tabla general'!$L$4,0))) + IF(AND($C14=N14,$D14=O14),'Tabla general'!$L$5,0)) -> 0 | S14: =IF(AND($C14="",$D14=""),0,IF(AND($C14>$D14,Q14>R14),'Tabla general'!$L$4,IF(AND($D14>$C14,R14>Q14),'Tabla general'!$L$4,IF(AND($C14=$D14,Q14=R14),'Tabla general'!$L$4,0))) + IF(AND($C14=Q14,$D14=R14),'Tabla general'!$L$5,0)) -> 0 | V14: =IF(AND($C14="",$D14=""),0,IF(AND($C14>$D14,T14>U14),'Tabla general'!$L$4,IF(AND($D14>$C14,U14>T14),'Tabla general'!$L$4,IF(AND($C14=$D14,T14=U14),'Tabla general'!$L$4,0))) + IF(AND($C14=T14,$D14=U14),'Tabla general'!$L$5,0)) -> 0 | Y14: =IF(AND($C14="",$D14=""),0,IF(AND($C14>$D14,W14>X14),'Tabla general'!$L$4,IF(AND($D14>$C14,X14>W14),'Tabla general'!$L$4,IF(AND($C14=$D14,W14=X14),'Tabla general'!$L$4,0))) + IF(AND($C14=W14,$D14=X14),'Tabla general'!$L$5,0)) -> 0 | AB14: =IF(AND($C14="",$D14=""),0,IF(AND($C14>$D14,Z14>AA14),'Tabla general'!$L$4,IF(AND($D14>$C14,AA14>Z14),'Tabla general'!$L$4,IF(AND($C14=$D14,Z14=AA14),'Tabla general'!$L$4,0))) + IF(AND($C14=Z14,$D14=AA14),'Tabla general'!$L$5,0)) -> 0 | AE14: =IF(AND($C14="",$D14=""),0,IF(AND($C14>$D14,AC14>AD14),'Tabla general'!$L$4,IF(AND($D14>$C14,AD14>AC14),'Tabla general'!$L$4,IF(AND($C14=$D14,AC14=AD14),'Tabla general'!$L$4,0))) + IF(AND($C14=AC14,$D14=AD14),'Tabla general'!$L$5,0)) -> 0 | AH14: =IF(AND($C14="",$D14=""),0,IF(AND($C14>$D14,AF14>AG14),'Tabla general'!$L$4,IF(AND($D14>$C14,AG14>AF14),'Tabla general'!$L$4,IF(AND($C14=$D14,AF14=AG14),'Tabla general'!$L$4,0))) + IF(AND($C14=AF14,$D14=AG14),'Tabla general'!$L$5,0)) -> 0 | AK14: =IF(AND($C14="",$D14=""),0,IF(AND($C14>$D14,AI14>AJ14),'Tabla general'!$L$4,IF(AND($D14>$C14,AJ14>AI14),'Tabla general'!$L$4,IF(AND($C14=$D14,AI14=AJ14),'Tabla general'!$L$4,0))) + IF(AND($C14=AI14,$D14=AJ14),'Tabla general'!$L$5,0)) -> 0 | AN14: =IF(AND($C14="",$D14=""),0,IF(AND($C14>$D14,AL14>AM14),'Tabla general'!$L$4,IF(AND($D14>$C14,AM14>AL14),'Tabla general'!$L$4,IF(AND($C14=$D14,AL14=AM14),'Tabla general'!$L$4,0))) + IF(AND($C14=AL14,$D14=AM14),'Tabla general'!$L$5,0)) -> 0 | AQ14: =IF(AND($C14="",$D14=""),0,IF(AND($C14>$D14,AO14>AP14),'Tabla general'!$L$4,IF(AND($D14>$C14,AP14>AO14),'Tabla general'!$L$4,IF(AND($C14=$D14,AO14=AP14),'Tabla general'!$L$4,0))) + IF(AND($C14=AO14,$D14=AP14),'Tabla general'!$L$5,0)) -> 0 | AT14: =IF(AND($C14="",$D14=""),0,IF(AND($C14>$D14,AR14>AS14),'Tabla general'!$L$4,IF(AND($D14>$C14,AS14>AR14),'Tabla general'!$L$4,IF(AND($C14=$D14,AR14=AS14),'Tabla general'!$L$4,0))) + IF(AND($C14=AR14,$D14=AS14),'Tabla general'!$L$5,0)) -> 0 | AW14: =IF(AND($C14="",$D14=""),0,IF(AND($C14>$D14,AU14>AV14),'Tabla general'!$L$4,IF(AND($D14>$C14,AV14>AU14),'Tabla general'!$L$4,IF(AND($C14=$D14,AU14=AV14),'Tabla general'!$L$4,0))) + IF(AND($C14=AU14,$D14=AV14),'Tabla general'!$L$5,0)) -> 0 | AZ14: =IF(AND($C14="",$D14=""),0,IF(AND($C14>$D14,AX14>AY14),'Tabla general'!$L$4,IF(AND($D14>$C14,AY14>AX14),'Tabla general'!$L$4,IF(AND($C14=$D14,AX14=AY14),'Tabla general'!$L$4,0))) + IF(AND($C14=AX14,$D14=AY14),'Tabla general'!$L$5,0)) -> 0
A15: Alemania | B15: México | G15: =IF(AND($C15="",$D15=""),0,IF(AND($C15>$D15,E15>F15),'Tabla general'!$L$4,IF(AND($D15>$C15,F15>E15),'Tabla general'!$L$4,IF(AND($C15=$D15,E15=F15),'Tabla general'!$L$4,0))) + IF(AND($C15=E15,$D15=F15),'Tabla general'!$L$5,0)) -> 0 | J15: =IF(AND($C15="",$D15=""),0,IF(AND($C15>$D15,H15>I15),'Tabla general'!$L$4,IF(AND($D15>$C15,I15>H15),'Tabla general'!$L$4,IF(AND($C15=$D15,H15=I15),'Tabla general'!$L$4,0))) + IF(AND($C15=H15,$D15=I15),'Tabla general'!$L$5,0)) -> 0 | M15: =IF(AND($C15="",$D15=""),0,IF(AND($C15>$D15,K15>L15),'Tabla general'!$L$4,IF(AND($D15>$C15,L15>K15),'Tabla general'!$L$4,IF(AND($C15=$D15,K15=L15),'Tabla general'!$L$4,0))) + IF(AND($C15=K15,$D15=L15),'Tabla general'!$L$5,0)) -> 0 | P15: =IF(AND($C15="",$D15=""),0,IF(AND($C15>$D15,N15>O15),'Tabla general'!$L$4,IF(AND($D15>$C15,O15>N15),'Tabla general'!$L$4,IF(AND($C15=$D15,N15=O15),'Tabla general'!$L$4,0))) + IF(AND($C15=N15,$D15=O15),'Tabla general'!$L$5,0)) -> 0 | S15: =IF(AND($C15="",$D15=""),0,IF(AND($C15>$D15,Q15>R15),'Tabla general'!$L$4,IF(AND($D15>$C15,R15>Q15),'Tabla general'!$L$4,IF(AND($C15=$D15,Q15=R15),'Tabla general'!$L$4,0))) + IF(AND($C15=Q15,$D15=R15),'Tabla general'!$L$5,0)) -> 0 | V15: =IF(AND($C15="",$D15=""),0,IF(AND($C15>$D15,T15>U15),'Tabla general'!$L$4,IF(AND($D15>$C15,U15>T15),'Tabla general'!$L$4,IF(AND($C15=$D15,T15=U15),'Tabla general'!$L$4,0))) + IF(AND($C15=T15,$D15=U15),'Tabla general'!$L$5,0)) -> 0 | Y15: =IF(AND($C15="",$D15=""),0,IF(AND($C15>$D15,W15>X15),'Tabla general'!$L$4,IF(AND($D15>$C15,X15>W15),'Tabla general'!$L$4,IF(AND($C15=$D15,W15=X15),'Tabla general'!$L$4,0))) + IF(AND($C15=W15,$D15=X15),'Tabla general'!$L$5,0)) -> 0 | AB15: =IF(AND($C15="",$D15=""),0,IF(AND($C15>$D15,Z15>AA15),'Tabla general'!$L$4,IF(AND($D15>$C15,AA15>Z15),'Tabla general'!$L$4,IF(AND($C15=$D15,Z15=AA15),'Tabla general'!$L$4,0))) + IF(AND($C15=Z15,$D15=AA15),'Tabla general'!$L$5,0)) -> 0 | AE15: =IF(AND($C15="",$D15=""),0,IF(AND($C15>$D15,AC15>AD15),'Tabla general'!$L$4,IF(AND($D15>$C15,AD15>AC15),'Tabla general'!$L$4,IF(AND($C15=$D15,AC15=AD15),'Tabla general'!$L$4,0))) + IF(AND($C15=AC15,$D15=AD15),'Tabla general'!$L$5,0)) -> 0 | AH15: =IF(AND($C15="",$D15=""),0,IF(AND($C15>$D15,AF15>AG15),'Tabla general'!$L$4,IF(AND($D15>$C15,AG15>AF15),'Tabla general'!$L$4,IF(AND($C15=$D15,AF15=AG15),'Tabla general'!$L$4,0))) + IF(AND($C15=AF15,$D15=AG15),'Tabla general'!$L$5,0)) -> 0 | AK15: =IF(AND($C15="",$D15=""),0,IF(AND($C15>$D15,AI15>AJ15),'Tabla general'!$L$4,IF(AND($D15>$C15,AJ15>AI15),'Tabla general'!$L$4,IF(AND($C15=$D15,AI15=AJ15),'Tabla general'!$L$4,0))) + IF(AND($C15=AI15,$D15=AJ15),'Tabla general'!$L$5,0)) -> 0 | AN15: =IF(AND($C15="",$D15=""),0,IF(AND($C15>$D15,AL15>AM15),'Tabla general'!$L$4,IF(AND($D15>$C15,AM15>AL15),'Tabla general'!$L$4,IF(AND($C15=$D15,AL15=AM15),'Tabla general'!$L$4,0))) + IF(AND($C15=AL15,$D15=AM15),'Tabla general'!$L$5,0)) -> 0 | AQ15: =IF(AND($C15="",$D15=""),0,IF(AND($C15>$D15,AO15>AP15),'Tabla general'!$L$4,IF(AND($D15>$C15,AP15>AO15),'Tabla general'!$L$4,IF(AND($C15=$D15,AO15=AP15),'Tabla general'!$L$4,0))) + IF(AND($C15=AO15,$D15=AP15),'Tabla general'!$L$5,0)) -> 0 | AT15: =IF(AND($C15="",$D15=""),0,IF(AND($C15>$D15,AR15>AS15),'Tabla general'!$L$4,IF(AND($D15>$C15,AS15>AR15),'Tabla general'!$L$4,IF(AND($C15=$D15,AR15=AS15),'Tabla general'!$L$4,0))) + IF(AND($C15=AR15,$D15=AS15),'Tabla general'!$L$5,0)) -> 0 | AW15: =IF(AND($C15="",$D15=""),0,IF(AND($C15>$D15,AU15>AV15),'Tabla general'!$L$4,IF(AND($D15>$C15,AV15>AU15),'Tabla general'!$L$4,IF(AND($C15=$D15,AU15=AV15),'Tabla general'!$L$4,0))) + IF(AND($C15=AU15,$D15=AV15),'Tabla general'!$L$5,0)) -> 0 | AZ15: =IF(AND($C15="",$D15=""),0,IF(AND($C15>$D15,AX15>AY15),'Tabla general'!$L$4,IF(AND($D15>$C15,AY15>AX15),'Tabla general'!$L$4,IF(AND($C15=$D15,AX15=AY15),'Tabla general'!$L$4,0))) + IF(AND($C15=AX15,$D15=AY15),'Tabla general'!$L$5,0)) -> 0
A16: Brasil | B16: Suiza | G16: =IF(AND($C16="",$D16=""),0,IF(AND($C16>$D16,E16>F16),'Tabla general'!$L$4,IF(AND($D16>$C16,F16>E16),'Tabla general'!$L$4,IF(AND($C16=$D16,E16=F16),'Tabla general'!$L$4,0))) + IF(AND($C16=E16,$D16=F16),'Tabla general'!$L$5,0)) -> 0 | J16: =IF(AND($C16="",$D16=""),0,IF(AND($C16>$D16,H16>I16),'Tabla general'!$L$4,IF(AND($D16>$C16,I16>H16),'Tabla general'!$L$4,IF(AND($C16=$D16,H16=I16),'Tabla general'!$L$4,0))) + IF(AND($C16=H16,$D16=I16),'Tabla general'!$L$5,0)) -> 0 | M16: =IF(AND($C16="",$D16=""),0,IF(AND($C16>$D16,K16>L16),'Tabla general'!$L$4,IF(AND($D16>$C16,L16>K16),'Tabla general'!$L$4,IF(AND($C16=$D16,K16=L16),'Tabla general'!$L$4,0))) + IF(AND($C16=K16,$D16=L16),'Tabla general'!$L$5,0)) -> 0 | P16: =IF(AND($C16="",$D16=""),0,IF(AND($C16>$D16,N16>O16),'Tabla general'!$L$4,IF(AND($D16>$C16,O16>N16),'Tabla general'!$L$4,IF(AND($C16=$D16,N16=O16),'Tabla general'!$L$4,0))) + IF(AND($C16=N16,$D16=O16),'Tabla general'!$L$5,0)) -> 0 | S16: =IF(AND($C16="",$D16=""),0,IF(AND($C16>$D16,Q16>R16),'Tabla general'!$L$4,IF(AND($D16>$C16,R16>Q16),'Tabla general'!$L$4,IF(AND($C16=$D16,Q16=R16),'Tabla general'!$L$4,0))) + IF(AND($C16=Q16,$D16=R16),'Tabla general'!$L$5,0)) -> 0 | V16: =IF(AND($C16="",$D16=""),0,IF(AND($C16>$D16,T16>U16),'Tabla general'!$L$4,IF(AND($D16>$C16,U16>T16),'Tabla general'!$L$4,IF(AND($C16=$D16,T16=U16),'Tabla general'!$L$4,0))) + IF(AND($C16=T16,$D16=U16),'Tabla general'!$L$5,0)) -> 0 | Y16: =IF(AND($C16="",$D16=""),0,IF(AND($C16>$D16,W16>X16),'Tabla general'!$L$4,IF(AND($D16>$C16,X16>W16),'Tabla general'!$L$4,IF(AND($C16=$D16,W16=X16),'Tabla general'!$L$4,0))) + IF(AND($C16=W16,$D16=X16),'Tabla general'!$L$5,0)) -> 0 | AB16: =IF(AND($C16="",$D16=""),0,IF(AND($C16>$D16,Z16>AA16),'Tabla general'!$L$4,IF(AND($D16>$C16,AA16>Z16),'Tabla general'!$L$4,IF(AND($C16=$D16,Z16=AA16),'Tabla general'!$L$4,0))) + IF(AND($C16=Z16,$D16=AA16),'Tabla general'!$L$5,0)) -> 0 | AE16: =IF(AND($C16="",$D16=""),0,IF(AND($C16>$D16,AC16>AD16),'Tabla general'!$L$4,IF(AND($D16>$C16,AD16>AC16),'Tabla general'!$L$4,IF(AND($C16=$D16,AC16=AD16),'Tabla general'!$L$4,0))) + IF(AND($C16=AC16,$D16=AD16),'Tabla general'!$L$5,0)) -> 0 | AH16: =IF(AND($C16="",$D16=""),0,IF(AND($C16>$D16,AF16>AG16),'Tabla general'!$L$4,IF(AND($D16>$C16,AG16>AF16),'Tabla general'!$L$4,IF(AND($C16=$D16,AF16=AG16),'Tabla general'!$L$4,0))) + IF(AND($C16=AF16,$D16=AG16),'Tabla general'!$L$5,0)) -> 0 | AK16: =IF(AND($C16="",$D16=""),0,IF(AND($C16>$D16,AI16>AJ16),'Tabla general'!$L$4,IF(AND($D16>$C16,AJ16>AI16),'Tabla general'!$L$4,IF(AND($C16=$D16,AI16=AJ16),'Tabla general'!$L$4,0))) + IF(AND($C16=AI16,$D16=AJ16),'Tabla general'!$L$5,0)) -> 0 | AN16: =IF(AND($C16="",$D16=""),0,IF(AND($C16>$D16,AL16>AM16),'Tabla general'!$L$4,IF(AND($D16>$C16,AM16>AL16),'Tabla general'!$L$4,IF(AND($C16=$D16,AL16=AM16),'Tabla general'!$L$4,0))) + IF(AND($C16=AL16,$D16=AM16),'Tabla general'!$L$5,0)) -> 0 | AQ16: =IF(AND($C16="",$D16=""),0,IF(AND($C16>$D16,AO16>AP16),'Tabla general'!$L$4,IF(AND($D16>$C16,AP16>AO16),'Tabla general'!$L$4,IF(AND($C16=$D16,AO16=AP16),'Tabla general'!$L$4,0))) + IF(AND($C16=AO16,$D16=AP16),'Tabla general'!$L$5,0)) -> 0 | AT16: =IF(AND($C16="",$D16=""),0,IF(AND($C16>$D16,AR16>AS16),'Tabla general'!$L$4,IF(AND($D16>$C16,AS16>AR16),'Tabla general'!$L$4,IF(AND($C16=$D16,AR16=AS16),'Tabla general'!$L$4,0))) + IF(AND($C16=AR16,$D16=AS16),'Tabla general'!$L$5,0)) -> 0 | AW16: =IF(AND($C16="",$D16=""),0,IF(AND($C16>$D16,AU16>AV16),'Tabla general'!$L$4,IF(AND($D16>$C16,AV16>AU16),'Tabla general'!$L$4,IF(AND($C16=$D16,AU16=AV16),'Tabla general'!$L$4,0))) + IF(AND($C16=AU16,$D16=AV16),'Tabla general'!$L$5,0)) -> 0 | AZ16: =IF(AND($C16="",$D16=""),0,IF(AND($C16>$D16,AX16>AY16),'Tabla general'!$L$4,IF(AND($D16>$C16,AY16>AX16),'Tabla general'!$L$4,IF(AND($C16=$D16,AX16=AY16),'Tabla general'!$L$4,0))) + IF(AND($C16=AX16,$D16=AY16),'Tabla general'!$L$5,0)) -> 0
A17: Suecia | B17: Rep.de Corea | G17: =IF(AND($C17="",$D17=""),0,IF(AND($C17>$D17,E17>F17),'Tabla general'!$L$4,IF(AND($D17>$C17,F17>E17),'Tabla general'!$L$4,IF(AND($C17=$D17,E17=F17),'Tabla general'!$L$4,0))) + IF(AND($C17=E17,$D17=F17),'Tabla general'!$L$5,0)) -> 0 | J17: =IF(AND($C17="",$D17=""),0,IF(AND($C17>$D17,H17>I17),'Tabla general'!$L$4,IF(AND($D17>$C17,I17>H17),'Tabla general'!$L$4,IF(AND($C17=$D17,H17=I17),'Tabla general'!$L$4,0))) + IF(AND($C17=H17,$D17=I17),'Tabla general'!$L$5,0)) -> 0 | M17: =IF(AND($C17="",$D17=""),0,IF(AND($C17>$D17,K17>L17),'Tabla general'!$L$4,IF(AND($D17>$C17,L17>K17),'Tabla general'!$L$4,IF(AND($C17=$D17,K17=L17),'Tabla general'!$L$4,0))) + IF(AND($C17=K17,$D17=L17),'Tabla general'!$L$5,0)) -> 0 | P17: =IF(AND($C17="",$D17=""),0,IF(AND($C17>$D17,N17>O17),'Tabla general'!$L$4,IF(AND($D17>$C17,O17>N17),'Tabla general'!$L$4,IF(AND($C17=$D17,N17=O17),'Tabla general'!$L$4,0))) + IF(AND($C17=N17,$D17=O17),'Tabla general'!$L$5,0)) -> 0 | S17: =IF(AND($C17="",$D17=""),0,IF(AND($C17>$D17,Q17>R17),'Tabla general'!$L$4,IF(AND($D17>$C17,R17>Q17),'Tabla general'!$L$4,IF(AND($C17=$D17,Q17=R17),'Tabla general'!$L$4,0))) + IF(AND($C17=Q17,$D17=R17),'Tabla general'!$L$5,0)) -> 0 | V17: =IF(AND($C17="",$D17=""),0,IF(AND($C17>$D17,T17>U17),'Tabla general'!$L$4,IF(AND($D17>$C17,U17>T17),'Tabla general'!$L$4,IF(AND($C17=$D17,T17=U17),'Tabla general'!$L$4,0))) + IF(AND($C17=T17,$D17=U17),'Tabla general'!$L$5,0)) -> 0 | Y17: =IF(AND($C17="",$D17=""),0,IF(AND($C17>$D17,W17>X17),'Tabla general'!$L$4,IF(AND($D17>$C17,X17>W17),'Tabla general'!$L$4,IF(AND($C17=$D17,W17=X17),'Tabla general'!$L$4,0))) + IF(AND($C17=W17,$D17=X17),'Tabla general'!$L$5,0)) -> 0 | AB17: =IF(AND($C17="",$D17=""),0,IF(AND($C17>$D17,Z17>AA17),'Tabla general'!$L$4,IF(AND($D17>$C17,AA17>Z17),'Tabla general'!$L$4,IF(AND($C17=$D17,Z17=AA17),'Tabla general'!$L$4,0))) + IF(AND($C17=Z17,$D17=AA17),'Tabla general'!$L$5,0)) -> 0 | AE17: =IF(AND($C17="",$D17=""),0,IF(AND($C17>$D17,AC17>AD17),'Tabla general'!$L$4,IF(AND($D17>$C17,AD17>AC17),'Tabla general'!$L$4,IF(AND($C17=$D17,AC17=AD17),'Tabla general'!$L$4,0))) + IF(AND($C17=AC17,$D17=AD17),'Tabla general'!$L$5,0)) -> 0 | AH17: =IF(AND($C17="",$D17=""),0,IF(AND($C17>$D17,AF17>AG17),'Tabla general'!$L$4,IF(AND($D17>$C17,AG17>AF17),'Tabla general'!$L$4,IF(AND($C17=$D17,AF17=AG17),'Tabla general'!$L$4,0))) + IF(AND($C17=AF17,$D17=AG17),'Tabla general'!$L$5,0)) -> 0 | AK17: =IF(AND($C17="",$D17=""),0,IF(AND($C17>$D17,AI17>AJ17),'Tabla general'!$L$4,IF(AND($D17>$C17,AJ17>AI17),'Tabla general'!$L$4,IF(AND($C17=$D17,AI17=AJ17),'Tabla general'!$L$4,0))) + IF(AND($C17=AI17,$D17=AJ17),'Tabla general'!$L$5,0)) -> 0 | AN17: =IF(AND($C17="",$D17=""),0,IF(AND($C17>$D17,AL17>AM17),'Tabla general'!$L$4,IF(AND($D17>$C17,AM17>AL17),'Tabla general'!$L$4,IF(AND($C17=$D17,AL17=AM17),'Tabla general'!$L$4,0))) + IF(AND($C17=AL17,$D17=AM17),'Tabla general'!$L$5,0)) -> 0 | AQ17: =IF(AND($C17="",$D17=""),0,IF(AND($C17>$D17,AO17>AP17),'Tabla general'!$L$4,IF(AND($D17>$C17,AP17>AO17),'Tabla general'!$L$4,IF(AND($C17=$D17,AO17=AP17),'Tabla general'!$L$4,0))) + IF(AND($C17=AO17,$D17=AP17),'Tabla general'!$L$5,0)) -> 0 | AT17: =IF(AND($C17="",$D17=""),0,IF(AND($C17>$D17,AR17>AS17),'Tabla general'!$L$4,IF(AND($D17>$C17,AS17>AR17),'Tabla general'!$L$4,IF(AND($C17=$D17,AR17=AS17),'Tabla general'!$L$4,0))) + IF(AND($C17=AR17,$D17=AS17),'Tabla general'!$L$5,0)) -> 0 | AW17: =IF(AND($C17="",$D17=""),0,IF(AND($C17>$D17,AU17>AV17),'Tabla general'!$L$4,IF(AND($D17>$C17,AV17>AU17),'Tabla general'!$L$4,IF(AND($C17=$D17,AU17=AV17),'Tabla general'!$L$4,0))) + IF(AND($C17=AU17,$D17=AV17),'Tabla general'!$L$5,0)) -> 0 | AZ17: =IF(AND($C17="",$D17=""),0,IF(AND($C17>$D17,AX17>AY17),'Tabla general'!$L$4,IF(AND($D17>$C17,AY17>AX17),'Tabla general'!$L$4,IF(AND($C17=$D17,AX17=AY17),'Tabla general'!$L$4,0))) + IF(AND($C17=AX17,$D17=AY17),'Tabla general'!$L$5,0)) -> 0
